Workbook

Sheet H1
A6: CORRELATIVO N°2 | G6: 45778 | H6: 45779 | I6: 45780 | J6: 45781 | K6: 45782 | L6: 45783 | M6: 45784 | N6: 45785 | O6: 45786 | P6: 45787 | Q6: 45788 | R6: 45789 | S6: 45790 | T6: 45791 | U6: 45792 | V6: 45793 | W6: 45794 | X6: 45795 | Y6: 45796 | Z6: 45797 | AA6: 45798 | AB6: 45799 | AC6: 45800 | AD6: 45801 | AE6: 45802 | AF6: 45803 | AG6: 45804 | AH6: 45805 | AI6: 45806 | AJ6: 45807 | AK6: 45808 | AL6: 01 AL 31 DE MAYO
B9: HAB | C9: APELLIDO PATERNO | D9: APELLIDO MATERNO | E9: NOMBRE | F9: RUT | AL9: D. OCUP | AM9: V. OCUP | AN9: T. OCUP.
A10: H1 | B10: 51 | C10: MORALES | D10: HERNANDEZ | E10: MATIAS | F10: 21456295-2 | G10: 1 | H10: 1 | I10: 1 | J10: 1 | K10: 1 | L10: 1 | M10: 1 | N10: 1 | O10: 1 | P10: 1 | AL10: =SUM(G10:AK10) -> 10 | AM10: 32000 | AN10: =AM10*AL10 -> 320000
A11: H1 | B11: 51 | C11: ORELLANA | D11: CASTILLO | E11: MAURICIO | F11: 16688300-8 | G11: 1 | H11: 1 | I11: 1 | J11: 1 | K11: 1 | L11: 1 | M11: 1 | N11: 1 | O11: 1 | P11: 1 | AL11: =SUM(G11:AK11) -> 10 | AM11: 32000 | AN11: =AM11*AL11 -> 320000
A12: H1 | B12: 56 | C12: LORCA | D12: GONZALEZ | E12: ROBERTO | F12: 19573463-1 | G12: 1 | H12: 1 | I12: 1 | J12: 1 | K12: 1 | L12: 1 | M12: 1 | N12: 1 | O12: 1 | P12: 1 | AL12: =SUM(G12:AK12) -> 10 | AM12: 32000 | AN12: =AM12*AL12 -> 320000
A13: H1 | B13: 56 | C13: LORCA | D13: GONZALEZ | E13: JOSE | F13: 20188147-1 | G13: 1 | H13: 1 | I13: 1 | J13: 1 | K13: 1 | L13: 1 | M13: 1 | N13: 1 | O13: 1 | P13: 1 | AL13: =SUM(G13:AK13) -> 10 | AM13: 32000 | AN13: =AM13*AL13 -> 320000
A14: H1 | B14: 57 | C14: ARAVENA | D14: LEYTON | E14: MAURICIO | F14: 17932208-0 | G14: 1 | H14: 1 | I14: 1 | J14: 1 | K14: 1 | L14: 1 | M14: 1 | N14: 1 | O14: 1 | P14: 1 | AL14: =SUM(G14:AK14) -> 10 | AM14: 32000 | AN14: =AM14*AL14 -> 320000
A15: H1 | B15: 57 | C15: URIBE | D15: VALENZUELA | E15: CARLOS | F15: 17209918-1 | G15: 1 | H15: 1 | I15: 1 | J15: 1 | K15: 1 | L15: 1 | M15: 1 | N15: 1 | O15: 1 | P15: 1 | AL15: =SUM(G15:AK15) -> 10 | AM15: 32000 | AN15: =AM15*AL15 -> 320000
A16: H1 | B16: 59 | C16: ARANCIBIA | D16: OVALLE | E16: ROBERTO | F16: 9347291-8 | G16: 1 | H16: 1 | I16: 1 | J16: 1 | K16: 1 | L16: 1 | M16: 1 | N16: 1 | O16: 1 | P16: 1 | AL16: =SUM(G16:AK16) -> 10 | AM16: 32000 | AN16: =AM16*AL16 -> 320000
A17: H1 | B17: 59 | C17: MORALES | D17: ARTEAGA | E17: JURGUEN | F17: 21462934-8 | G17: 1 | H17: 1 | I17: 1 | J17: 1 | K17: 1 | L17: 1 | M17: 1 | N17: 1 | O17: 1 | P17: 1 | AL17: =SUM(G17:AK17) -> 10 | AM17: 32000 | AN17: =AM17*AL17 -> 320000
A18: H1 | B18: 61 | C18: GALAZ | D18: ZUÑIGA | E18: PATRICIO | F18: 12175296-4 | G18: 1 | H18: 1 | I18: 1 | J18: 1 | K18: 1 | L18: 1 | M18: 1 | N18: 1 | O18: 1 | P18: 1 | AL18: =SUM(G18:AK18) -> 10 | AM18: 32000 | AN18: =AM18*AL18 -> 320000
A19: H1 | B19: 61 | C19: RETAMAL | D19: CASTRO | E19: BENJAMIN | F19: 19346121-2 | G19: 1 | H19: 1 | I19: 1 | J19: 1 | K19: 1 | L19: 1 | M19: 1 | N19: 1 | O19: 1 | P19: 1 | AL19: =SUM(G19:AK19) -> 10 | AM19: 32000 | AN19: =AM19*AL19 -> 320000
A20: H1 | B20: 65 | C20: JORQUERA | D20: GENERAL | E20: ALFREDO | F20: 16678159-0 | G20: 1 | H20: 1 | I20: 1 | J20: 1 | K20: 1 | L20: 1 | M20: 1 | N20: 1 | O20: 1 | P20: 1 | AL20: =SUM(G20:AK20) -> 10 | AM20: 32000 | AN20: =AM20*AL20 -> 320000
A21: H1 | B21: 65 | C21: SOLIS | D21: HIDALGO | E21: ALEJANDRA | F21: 17078357-3 | G21: 1 | H21: 1 | I21: 1 | J21: 1 | K21: 1 | L21: 1 | M21: 1 | N21: 1 | O21: 1 | P21: 1 | AL21: =SUM(G21:AK21) -> 10 | AM21: 32000 | AN21: =AM21*AL21 -> 320000
A22: H1 | B22: 67 | C22: ÑANCO | D22: MILLALEN | E22: LUIS | F22: 15248769-K | G22: 1 | H22: 1 | I22: 1 | J22: 1 | K22: 1 | L22: 1 | M22: 1 | N22: 1 | O22: 1 | P22: 1 | AL22: =SUM(G22:AK22) -> 10 | AM22: 32000 | AN22: =AM22*AL22 -> 320000
A23: H1 | B23: 67 | C23: RIOS | D23: BAEZA | E23: LUIS | G23: 1 | H23: 1 | I23: 1 | J23: 1 | K23: 1 | L23: 1 | M23: 1 | N23: 1 | O23: 1 | P23: 1 | AL23: =SUM(G23:AK23) -> 10 | AM23: 32000 | AN23: =AM23*AL23 -> 320000
A24: H1 | B24: 69 | C24: PICHON | D24: CORNEJO | E24: MARCO | F24: 12915179-K | G24: 1 | H24: 1 | I24: 1 | J24: 1 | K24: 1 | L24: 1 | M24: 1 | N24: 1 | O24: 1 | P24: 1 | AL24: =SUM(G24:AK24) -> 10 | AM24: 32000 | AN24: =AM24*AL24 -> 320000
A25: H1 | B25: 69 | C25: INOSTROZA | D25: INOSTROZA | E25: RINDOLFO | F25: 11585182-9 | G25: 1 | H25: 1 | I25: 1 | J25: 1 | K25: 1 | L25: 1 | M25: 1 | N25: 1 | O25: 1 | P25: 1 | AL25: =SUM(G25:AK25) -> 10 | AM25: 32000 | AN25: =AM25*AL25 -> 320000
A26: H1 | B26: 71 | C26: CAYUQUEO | D26: CAMPOS | E26: ERWIN | F26: 17261752-2 | G26: 1 | H26: 1 | I26: 1 | J26: 1 | K26: 1 | L26: 1 | M26: 1 | N26: 1 | O26: 1 | P26: 1 | AL26: =SUM(G26:AK26) -> 10 | AM26: 32000 | AN26: =AM26*AL26 -> 320000
A27: H1 | B27: 71 | C27: FUENTELABA | D27: MUÑOZ | E27: PABLO | F27: 15508059-0 | G27: 1 | H27: 1 | I27: 1 | J27: 1 | K27: 1 | L27: 1 | M27: 1 | N27: 1 | O27: 1 | P27: 1 | AL27: =SUM(G27:AK27) -> 10 | AM27: 32000 | AN27: =AM27*AL27 -> 320000
A28: H1 | B28: 5 | C28: MORALES | D28: LOPEZ | E28: IVAN | F28: 12602975-6 | N28: 1 | O28: 1 | P28: 1 | Q28: 1 | R28: 1 | S28: 1 | T28: 1 | U28: 1 | V28: 1 | W28: 1 | X28: 1 | Y28: 1 | Z28: 1 | AA28: 1 | AL28: =SUM(G28:AK28) -> 14 | AM28: 32000 | AN28: =AM28*AL28 -> 448000
A29: H1 | B29: 5 | C29: VENEGAS | D29: CARES | E29: CRISTIAN | F29: 12512803-3 | N29: 1 | O29: 1 | P29: 1 | Q29: 1 | R29: 1 | S29: 1 | T29: 1 | U29: 1 | V29: 1 | W29: 1 | X29: 1 | Y29: 1 | Z29: 1 | AA29: 1 | AL29: =SUM(G29:AK29) -> 14 | AM29: 32000 | AN29: =AM29*AL29 -> 448000
A30: H1 | B30: 7 | C30: ACEVEDO | D30: LETELIER | E30: CRISTIAN | F30: 16856842-8 | N30: 1 | O30: 1 | P30: 1 | Q30: 1 | R30: 1 | S30: 1 | T30: 1 | U30: 1 | V30: 1 | W30: 1 | X30: 1 | Y30: 1 | Z30: 1 | AA30: 1 | AL30: =SUM(G30:AK30) -> 14 | AM30: 32000 | AN30: =AM30*AL30 -> 448000
A31: H1 | B31: 7 | C31: RECABAL | D31: GONZALEZ | E31: CLAUDIO | F31: 13355393-2 | N31: 1 | O31: 1 | P31: 1 | Q31: 1 | R31: 1 | S31: 1 | T31: 1 | U31: 1 | V31: 1 | W31: 1 | X31: 1 | Y31: 1 | Z31: 1 | AA31: 1 | AL31: =SUM(G31:AK31) -> 14 | AM31: 32000 | AN31: =AM31*AL31 -> 448000
A32: H1 | B32: 8 | C32: BEROIZA | D32: RAILAF | E32: NICOLAS | F32: 19463033-6 | N32: 1 | O32: 1 | P32: 1 | Q32: 1 | R32: 1 | S32: 1 | T32: 1 | U32: 1 | V32: 1 | W32: 1 | X32: 1 | Y32: 1 | Z32: 1 | AA32: 1 | AL32: =SUM(G32:AK32) -> 14 | AM32: 32000 | AN32: =AM32*AL32 -> 448000
A33: H1 | B33: 8 | C33: CALPIQUEO | D33: PAILLACAN | E33: ALIRO | F33: 15239015-7 | N33: 1 | O33: 1 | P33: 1 | Q33: 1 | R33: 1 | S33: 1 | T33: 1 | U33: 1 | V33: 1 | W33: 1 | X33: 1 | Y33: 1 | Z33: 1 | AA33: 1 | AL33: =SUM(G33:AK33) -> 14 | AM33: 32000 | AN33: =AM33*AL33 -> 448000
A34: H1 | B34: 9 | C34: MUÑOZ | D34: QUEZADA | E34: MIGUEL | F34: 15819396-5 | N34: 1 | O34: 1 | P34: 1 | Q34: 1 | R34: 1 | S34: 1 | T34: 1 | U34: 1 | V34: 1 | W34: 1 | X34: 1 | Y34: 1 | Z34: 1 | AA34: 1 | AL34: =SUM(G34:AK34) -> 14 | AM34: 32000 | AN34: =AM34*AL34 -> 448000
A35: H1 | B35: 9 | C35: VARGAS | D35: FERNÁNDEZ | E35: CARLOS | F35: 8499733-1 | N35: 1 | O35: 1 | P35: 1 | Q35: 1 | R35: 1 | S35: 1 | T35: 1 | U35: 1 | V35: 1 | W35: 1 | X35: 1 | Y35: 1 | Z35: 1 | AA35: 1 | AL35: =SUM(G35:AK35) -> 14 | AM35: 32000 | AN35: =AM35*AL35 -> 448000
A36: H1 | B36: 10 | C36: ORTIZ | D36: SANTELICES | E36: ALEJANDRO | F36: 13856349-9 | N36: 1 | O36: 1 | P36: 1 | Q36: 1 | R36: 1 | S36: 1 | T36: 1 | U36: 1 | V36: 1 | W36: 1 | X36: 1 | Y36: 1 | Z36: 1 | AA36: 1 | AL36: =SUM(G36:AK36) -> 14 | AM36: 32000 | AN36: =AM36*AL36 -> 448000
A37: H1 | B37: 10 | C37: PIZARRO | D37: KLEIN | E37: LUIS | F37: 12501155-1 | N37: 1 | O37: 1 | P37: 1 | Q37: 1 | R37: 1 | S37: 1 | T37: 1 | U37: 1 | V37: 1 | W37: 1 | X37: 1 | Y37: 1 | Z37: 1 | AA37: 1 | AL37: =SUM(G37:AK37) -> 14 | AM37: 32000 | AN37: =AM37*AL37 -> 448000
A38: H1 | B38: 11 | C38: MORAGA | D38: POBLETE | E38: IGNACIO | F38: 19777682-K | N38: 1 | O38: 1 | P38: 1 | Q38: 1 | R38: 1 | S38: 1 | T38: 1 | U38: 1 | V38: 1 | W38: 1 | X38: 1 | Y38: 1 | Z38: 1 | AA38: 1 | AL38: =SUM(G38:AK38) -> 14 | AM38: 32000 | AN38: =AM38*AL38 -> 448000
A39: H1 | B39: 11 | C39: PAINEMIL | D39: AVILA | E39: MATIAS | F39: 20932689-2 | N39: 1 | O39: 1 | P39: 1 | Q39: 1 | R39: 1 | S39: 1 | T39: 1 | U39: 1 | V39: 1 | W39: 1 | X39: 1 | Y39: 1 | Z39: 1 | AA39: 1 | AL39: =SUM(G39:AK39) -> 14 | AM39: 32000 | AN39: =AM39*AL39 -> 448000
A40: H1 | B40: 14 | C40: AYALA | D40: MIRANDA | E40: HUMBERTO | F40: 8849655-8 | N40: 1 | O40: 1 | P40: 1 | Q40: 1 | R40: 1 | S40: 1 | T40: 1 | U40: 1 | V40: 1 | W40: 1 | X40: 1 | Y40: 1 | Z40: 1 | AL40: =SUM(G40:AK40) -> 13 | AM40: 32000 | AN40: =AM40*AL40 -> 416000
A41: H1 | B41: 14 | C41: LLANCAPAN | D41: CASTILLO | E41: MICHEL | F41: 13199156-8 | N41: 1 | O41: 1 | P41: 1 | Q41: 1 | R41: 1 | S41: 1 | T41: 1 | U41: 1 | V41: 1 | W41: 1 | X41: 1 | Y41: 1 | Z41: 1 | AA41: 1 | AL41: =SUM(G41:AK41) -> 14 | AM41: 32000 | AN41: =AM41*AL41 -> 448000
A42: H1 | B42: 22 | C42: CABRERA | D42: ALARCON | E42: ULICES | F42: 49343664 | N42: 1 | O42: 1 | P42: 1 | Q42: 1 | R42: 1 | S42: 1 | T42: 1 | U42: 1 | V42: 1 | W42: 1 | X42: 1 | Y42: 1 | Z42: 1 | AA42: 1 | AL42: =SUM(G42:AK42) -> 14 | AM42: 32000 | AN42: =AM42*AL42 -> 448000
A43: H1 | B43: 22 | C43: GARCIA | D43: SAAVEDRA | E43: AMERICO | F43: 124907860 | N43: 1 | O43: 1 | P43: 1 | Q43: 1 | R43: 1 | S43: 1 | T43: 1 | U43: 1 | V43: 1 | W43: 1 | X43: 1 | Y43: 1 | Z43: 1 | AA43: 1 | AL43: =SUM(G43:AK43) -> 14 | AM43: 32000 | AN43: =AM43*AL43 -> 448000
A44: H1 | B44: 24 | C44: TORRE | D44: VALENZUELA | E44: LIDO | F44: 9771848 | N44: 1 | O44: 1 | P44: 1 | Q44: 1 | R44: 1 | S44: 1 | T44: 1 | U44: 1 | V44: 1 | W44: 1 | X44: 1 | Y44: 1 | Z44: 1 | AA44: 1 | AL44: =SUM(G44:AK44) -> 14 | AM44: 32000 | AN44: =AM44*AL44 -> 448000
A45: H1 | B45: 24 | C45: GONZALEZ | D45: PALOMINO | E45: LUIS | F45: 123912862 | N45: 1 | O45: 1 | P45: 1 | Q45: 1 | R45: 1 | S45: 1 | T45: 1 | U45: 1 | V45: 1 | W45: 1 | X45: 1 | Y45: 1 | Z45: 1 | AA45: 1 | AL45: =SUM(G45:AK45) -> 14 | AM45: 32000 | AN45: =AM45*AL45 -> 448000
A46: H1 | B46: 35 | C46: DONOSO | D46: CORTES | E46: JUAN | F46: 20681999-5 | N46: 1 | O46: 1 | P46: 1 | Q46: 1 | R46: 1 | S46: 1 | T46: 1 | U46: 1 | V46: 1 | W46: 1 | X46: 1 | Y46: 1 | Z46: 1 | AA46: 1 | AL46: =SUM(G46:AK46) -> 14 | AM46: 32000 | AN46: =AM46*AL46 -> 448000
A47: H1 | B47: 35 | C47: MARAMBIO | D47: SALINAS | E47: PABLO | F47: 9253816-8 | N47: 1 | O47: 1 | P47: 1 | Q47: 1 | R47: 1 | S47: 1 | T47: 1 | U47: 1 | V47: 1 | W47: 1 | X47: 1 | Y47: 1 | Z47: 1 | AA47: 1 | AL47: =SUM(G47:AK47) -> 14 | AM47: 32000 | AN47: =AM47*AL47 -> 448000
...

Sheet H3
A6: CORRELATIVO N°2 | G6: 45778 | H6: 45779 | I6: 45780 | J6: 45781 | K6: 45782 | L6: 45783 | M6: 45784 | N6: 45785 | O6: 45786 | P6: 45787 | Q6: 45788 | R6: 45789 | S6: 45790 | T6: 45791 | U6: 45792 | V6: 45793 | W6: 45794 | X6: 45795 | Y6: 45796 | Z6: 45797 | AA6: 45798 | AB6: 45799 | AC6: 45800 | AD6: 45801 | AE6: 45802 | AF6: 45803 | AG6: 45804 | AH6: 45805 | AI6: 45806 | AJ6: 45807 | AK6: 45808 | AL6: 01 AL 31 DE MAYO
B9: HAB | C9: APELLIDO PATERNO | D9: APELLIDO MATERNO | E9: NOMBRE | F9: RUT | AL9: D. OCUP | AM9: V. OCUP | AN9: T. OCUP.
A10: H3 | B10: 51 | C10: MORALES | D10: HERNANDEZ | E10: MATIAS | F10: 21456295-2 | G10: 1 | H10: 1 | I10: 1 | J10: 1 | K10: 1 | L10: 1 | M10: 1 | N10: 1 | O10: 1 | P10: 1 | Q10: 1 | R10: 1 | AL10: =SUM(G10:AK10) -> 12 | AM10: 32000 | AN10: =AM10*AL10 -> 384000
A11: H3 | B11: 51 | C11: ORELLANA | D11: CASTILLO | E11: MAURICIO | F11: 16688300-8 | G11: 1 | H11: 1 | I11: 1 | J11: 1 | K11: 1 | L11: 1 | M11: 1 | N11: 1 | O11: 1 | P11: 1 | Q11: 1 | R11: 1 | AL11: =SUM(G11:AK11) -> 12 | AM11: 32000 | AN11: =AM11*AL11 -> 384000
A12: H3 | B12: 56 | C12: LORCA | D12: GONZALEZ | E12: ROBERTO | F12: 19573463-1 | G12: 1 | H12: 1 | I12: 1 | J12: 1 | K12: 1 | L12: 1 | M12: 1 | N12: 1 | O12: 1 | P12: 1 | Q12: 1 | R12: 1 | AL12: =SUM(G12:AK12) -> 12 | AM12: 32000 | AN12: =AM12*AL12 -> 384000
A13: H3 | B13: 56 | C13: LORCA | D13: GONZALEZ | E13: JOSE | F13: 20188147-1 | G13: 1 | H13: 1 | I13: 1 | J13: 1 | K13: 1 | L13: 1 | M13: 1 | N13: 1 | O13: 1 | P13: 1 | Q13: 1 | R13: 1 | AL13: =SUM(G13:AK13) -> 12 | AM13: 32000 | AN13: =AM13*AL13 -> 384000
A14: H3 | B14: 57 | C14: ARAVENA | D14: LEYTON | E14: MAURICIO | F14: 17932208-0 | G14: 1 | H14: 1 | I14: 1 | J14: 1 | K14: 1 | L14: 1 | M14: 1 | N14: 1 | O14: 1 | P14: 1 | Q14: 1 | R14: 1 | AL14: =SUM(G14:AK14) -> 12 | AM14: 32000 | AN14: =AM14*AL14 -> 384000
A15: H3 | B15: 57 | C15: URIBE | D15: VALENZUELA | E15: CARLOS | F15: 17209918-1 | G15: 1 | H15: 1 | I15: 1 | J15: 1 | K15: 1 | L15: 1 | M15: 1 | N15: 1 | O15: 1 | P15: 1 | Q15: 1 | R15: 1 | AL15: =SUM(G15:AK15) -> 12 | AM15: 32000 | AN15: =AM15*AL15 -> 384000
A16: H3 | B16: 59 | C16: ARANCIBIA | D16: OVALLE | E16: ROBERTO | F16: 9347291-8 | G16: 1 | H16: 1 | I16: 1 | J16: 1 | K16: 1 | L16: 1 | M16: 1 | N16: 1 | O16: 1 | P16: 1 | Q16: 1 | R16: 1 | AL16: =SUM(G16:AK16) -> 12 | AM16: 32000 | AN16: =AM16*AL16 -> 384000
A17: H3 | B17: 59 | C17: MORALES | D17: ARTEAGA | E17: JURGUEN | F17: 21462934-8 | G17: 1 | H17: 1 | I17: 1 | J17: 1 | K17: 1 | L17: 1 | M17: 1 | N17: 1 | O17: 1 | P17: 1 | Q17: 1 | R17: 1 | AL17: =SUM(G17:AK17) -> 12 | AM17: 32000 | AN17: =AM17*AL17 -> 384000
A18: H3 | B18: 61 | C18: GALAZ | D18: ZUÑIGA | E18: PATRICIO | F18: 12175296-4 | G18: 1 | H18: 1 | I18: 1 | J18: 1 | K18: 1 | L18: 1 | M18: 1 | N18: 1 | O18: 1 | P18: 1 | Q18: 1 | R18: 1 | AL18: =SUM(G18:AK18) -> 12 | AM18: 32000 | AN18: =AM18*AL18 -> 384000
A19: H3 | B19: 61 | C19: RETAMAL | D19: CASTRO | E19: BENJAMIN | F19: 19346121-2 | G19: 1 | H19: 1 | I19: 1 | J19: 1 | K19: 1 | L19: 1 | M19: 1 | N19: 1 | O19: 1 | P19: 1 | Q19: 1 | R19: 1 | AL19: =SUM(G19:AK19) -> 12 | AM19: 32000 | AN19: =AM19*AL19 -> 384000
A20: H3 | B20: 65 | C20: JORQUERA | D20: GENERAL | E20: ALFREDO | F20: 16678159-0 | G20: 1 | H20: 1 | I20: 1 | J20: 1 | K20: 1 | L20: 1 | M20: 1 | N20: 1 | O20: 1 | P20: 1 | Q20: 1 | R20: 1 | AL20: =SUM(G20:AK20) -> 12 | AM20: 32000 | AN20: =AM20*AL20 -> 384000
A21: H3 | B21: 65 | C21: SOLIS | D21: HIDALGO | E21: ALEJANDRA | F21: 17078357-3 | G21: 1 | H21: 1 | I21: 1 | J21: 1 | K21: 1 | L21: 1 | M21: 1 | N21: 1 | O21: 1 | P21: 1 | Q21: 1 | R21: 1 | AL21: =SUM(G21:AK21) -> 12 | AM21: 32000 | AN21: =AM21*AL21 -> 384000
A22: H3 | B22: 67 | C22: ÑANCO | D22: MILLALEN | E22: LUIS | F22: 15248769-K | G22: 1 | H22: 1 | I22: 1 | J22: 1 | K22: 1 | L22: 1 | M22: 1 | N22: 1 | O22: 1 | P22: 1 | Q22: 1 | R22: 1 | AL22: =SUM(G22:AK22) -> 12 | AM22: 32000 | AN22: =AM22*AL22 -> 384000
A23: H3 | B23: 67 | C23: RIOS | D23: BAEZA | E23: LUIS | G23: 1 | H23: 1 | I23: 1 | J23: 1 | K23: 1 | L23: 1 | M23: 1 | N23: 1 | O23: 1 | P23: 1 | Q23: 1 | R23: 1 | AL23: =SUM(G23:AK23) -> 12 | AM23: 32000 | AN23: =AM23*AL23 -> 384000
A24: H3 | B24: 69 | C24: PICHON | D24: CORNEJO | E24: MARCO | F24: 12915179-K | G24: 1 | H24: 1 | I24: 1 | J24: 1 | K24: 1 | L24: 1 | M24: 1 | N24: 1 | O24: 1 | P24: 1 | Q24: 1 | R24: 1 | AL24: =SUM(G24:AK24) -> 12 | AM24: 32000 | AN24: =AM24*AL24 -> 384000
A25: H3 | B25: 69 | C25: INOSTROZA | D25: INOSTROZA | E25: RINDOLFO | F25: 11585182-9 | G25: 1 | H25: 1 | I25: 1 | J25: 1 | K25: 1 | L25: 1 | M25: 1 | N25: 1 | O25: 1 | P25: 1 | Q25: 1 | R25: 1 | AL25: =SUM(G25:AK25) -> 12 | AM25: 32000 | AN25: =AM25*AL25 -> 384000
A26: H3 | B26: 71 | C26: CAYUQUEO | D26: CAMPOS | E26: ERWIN | F26: 17261752-2 | G26: 1 | H26: 1 | I26: 1 | J26: 1 | K26: 1 | L26: 1 | M26: 1 | N26: 1 | O26: 1 | P26: 1 | Q26: 1 | R26: 1 | AL26: =SUM(G26:AK26) -> 12 | AM26: 32000 | AN26: =AM26*AL26 -> 384000
A27: H3 | B27: 71 | C27: FUENTELABA | D27: MUÑOZ | E27: PABLO | F27: 15508059-0 | G27: 1 | H27: 1 | I27: 1 | J27: 1 | K27: 1 | L27: 1 | M27: 1 | N27: 1 | O27: 1 | P27: 1 | Q27: 1 | R27: 1 | AL27: =SUM(G27:AK27) -> 12 | AM27: 32000 | AN27: =AM27*AL27 -> 384000
A28: H3 | B28: 11 | C28: ANCANAO | D28: RODRIGUEZ | E28: JUAN | F28: 15210383-2 | N28: 1 | O28: 1 | P28: 1 | Q28: 1 | R28: 1 | S28: 1 | T28: 1 | U28: 1 | V28: 1 | W28: 1 | X28: 1 | Y28: 1 | Z28: 1 | AA28: 1 | AL28: =SUM(G28:AK28) -> 14 | AM28: 32000 | AN28: =AM28*AL28 -> 448000
A29: H3 | B29: 11 | C29: COFRE | D29: TRONCOSO | E29: PATRICIO | F29: 13155394-3 | N29: 1 | O29: 1 | P29: 1 | Q29: 1 | R29: 1 | S29: 1 | T29: 1 | U29: 1 | V29: 1 | W29: 1 | X29: 1 | Y29: 1 | Z29: 1 | AA29: 1 | AL29: =SUM(G29:AK29) -> 14 | AM29: 32000 | AN29: =AM29*AL29 -> 448000
A30: H3 | B30: 15 | C30: CISTERNAS | D30: MACAYA | E30: MOISES | F30: 12980913-2 | N30: 1 | O30: 1 | P30: 1 | Q30: 1 | R30: 1 | S30: 1 | T30: 1 | U30: 1 | V30: 1 | W30: 1 | X30: 1 | Y30: 1 | Z30: 1 | AA30: 1 | AL30: =SUM(G30:AK30) -> 14 | AM30: 32000 | AN30: =AM30*AL30 -> 448000
A31: H3 | B31: 15 | C31: FERNANDEZ | D31: VILLAGRAN | E31: HECTOR | F31: 10571908-6 | N31: 1 | O31: 1 | P31: 1 | Q31: 1 | R31: 1 | S31: 1 | T31: 1 | U31: 1 | V31: 1 | W31: 1 | X31: 1 | Y31: 1 | Z31: 1 | AA31: 1 | AL31: =SUM(G31:AK31) -> 14 | AM31: 32000 | AN31: =AM31*AL31 -> 448000
A32: H3 | B32: 17 | C32: CARTES | D32: ARRIAGADA | E32: MARCELO | F32: 19767976-K | N32: 1 | O32: 1 | P32: 1 | Q32: 1 | R32: 1 | S32: 1 | T32: 1 | U32: 1 | V32: 1 | W32: 1 | X32: 1 | Y32: 1 | Z32: 1 | AA32: 1 | AL32: =SUM(G32:AK32) -> 14 | AM32: 32000 | AN32: =AM32*AL32 -> 448000
A33: H3 | B33: 17 | C33: JARA | D33: ZAPATA | E33: JUAN | F33: 14573834-2 | N33: 1 | O33: 1 | P33: 1 | Q33: 1 | R33: 1 | S33: 1 | T33: 1 | U33: 1 | V33: 1 | W33: 1 | X33: 1 | Y33: 1 | Z33: 1 | AA33: 1 | AL33: =SUM(G33:AK33) -> 14 | AM33: 32000 | AN33: =AM33*AL33 -> 448000
A34: H3 | B34: 29 | C34: ARENAS | D34: MANRIQUEZ | E34: DANIEL | F34: 11179233-K | N34: 1 | O34: 1 | P34: 1 | Q34: 1 | R34: 1 | S34: 1 | T34: 1 | U34: 1 | V34: 1 | W34: 1 | X34: 1 | Y34: 1 | Z34: 1 | AA34: 1 | AL34: =SUM(G34:AK34) -> 14 | AM34: 32000 | AN34: =AM34*AL34 -> 448000
A35: H3 | B35: 29 | C35: TORRES | D35: BENITEZ | E35: ERIK | F35: 17870662-4 | N35: 1 | O35: 1 | P35: 1 | Q35: 1 | R35: 1 | S35: 1 | T35: 1 | U35: 1 | V35: 1 | W35: 1 | X35: 1 | Y35: 1 | Z35: 1 | AA35: 1 | AL35: =SUM(G35:AK35) -> 14 | AM35: 32000 | AN35: =AM35*AL35 -> 448000
A36: H3 | B36: 30 | C36: BRUNA | D36: ARAYA | E36: EDUARDO | F36: 16325978-8 | R36: 1 | S36: 1 | T36: 1 | U36: 1 | V36: 1 | W36: 1 | X36: 1 | Y36: 1 | Z36: 1 | AA36: 1 | AL36: =SUM(G36:AK36) -> 10 | AM36: 32000 | AN36: =AM36*AL36 -> 320000
A37: H3 | B37: 34 | C37: ESCOBAR | D37: ARRIAGADA | E37: PATRICIO | F37: 18405090-0 | N37: 1 | O37: 1 | P37: 1 | Q37: 1 | R37: 1 | S37: 1 | T37: 1 | U37: 1 | V37: 1 | W37: 1 | X37: 1 | Y37: 1 | Z37: 1 | AA37: 1 | AL37: =SUM(G37:AK37) -> 14 | AM37: 32000 | AN37: =AM37*AL37 -> 448000
A38: H3 | B38: 34 | C38: FIGUEROA | D38: MUÑOZ | E38: SERGIO | F38: 11215037-4 | N38: 1 | O38: 1 | P38: 1 | Q38: 1 | R38: 1 | S38: 1 | T38: 1 | U38: 1 | V38: 1 | W38: 1 | X38: 1 | Y38: 1 | Z38: 1 | AA38: 1 | AL38: =SUM(G38:AK38) -> 14 | AM38: 32000 | AN38: =AM38*AL38 -> 448000
A39: H3 | B39: 40 | C39: CHURATA | D39: CHUQUIRA | E39: ELISEO | F39: 44472068-9 | N39: 1 | O39: 1 | P39: 1 | Q39: 1 | R39: 1 | S39: 1 | T39: 1 | U39: 1 | V39: 1 | W39: 1 | X39: 1 | Y39: 1 | Z39: 1 | AA39: 1 | AL39: =SUM(G39:AK39) -> 14 | AM39: 32000 | AN39: =AM39*AL39 -> 448000
A40: H3 | B40: 40 | C40: MATO | D40: FLORES | E40: ISAAC | F40: 44471932-K | N40: 1 | O40: 1 | P40: 1 | Q40: 1 | R40: 1 | S40: 1 | T40: 1 | U40: 1 | V40: 1 | W40: 1 | X40: 1 | Y40: 1 | Z40: 1 | AA40: 1 | AL40: =SUM(G40:AK40) -> 14 | AM40: 32000 | AN40: =AM40*AL40 -> 448000
A41: H3 | B41: 42 | C41: ALFARO | D41: ALFARO | E41: BENITO | F41: 16054392-2 | N41: 1 | O41: 1 | P41: 1 | Q41: 1 | R41: 1 | S41: 1 | T41: 1 | U41: 1 | V41: 1 | W41: 1 | X41: 1 | Y41: 1 | Z41: 1 | AA41: 1 | AL41: =SUM(G41:AK41) -> 14 | AM41: 32000 | AN41: =AM41*AL41 -> 448000
A42: H3 | B42: 42 | C42: TECHELET | E42: PIERRE | F42: 25980292-K | N42: 1 | O42: 1 | P42: 1 | Q42: 1 | R42: 1 | S42: 1 | T42: 1 | U42: 1 | V42: 1 | W42: 1 | X42: 1 | Y42: 1 | Z42: 1 | AA42: 1 | AL42: =SUM(G42:AK42) -> 14 | AM42: 32000 | AN42: =AM42*AL42 -> 448000
A43: H3 | B43: 43 | C43: BALDEON | D43: PEÑA | E43: CLEMENTE | F43: 44472381-5 | N43: 1 | O43: 1 | P43: 1 | Q43: 1 | R43: 1 | S43: 1 | T43: 1 | U43: 1 | V43: 1 | W43: 1 | X43: 1 | Y43: 1 | Z43: 1 | AA43: 1 | AL43: =SUM(G43:AK43) -> 14 | AM43: 32000 | AN43: =AM43*AL43 -> 448000
A44: H3 | B44: 43 | C44: CAGLLAGUA | D44: ANGELINO | E44: HUGO | F44: 12484785-7 | N44: 1 | O44: 1 | P44: 1 | Q44: 1 | R44: 1 | S44: 1 | T44: 1 | U44: 1 | V44: 1 | W44: 1 | X44: 1 | Y44: 1 | Z44: 1 | AA44: 1 | AL44: =SUM(G44:AK44) -> 14 | AM44: 32000 | AN44: =AM44*AL44 -> 448000
A45: H3 | B45: 47 | C45: PANDURO | D45: DÍAZ | E45: BILLY | F45: 44472384-K | N45: 1 | O45: 1 | P45: 1 | Q45: 1 | R45: 1 | S45: 1 | T45: 1 | U45: 1 | V45: 1 | W45: 1 | X45: 1 | Y45: 1 | Z45: 1 | AA45: 1 | AL45: =SUM(G45:AK45) -> 14 | AM45: 32000 | AN45: =AM45*AL45 -> 448000
A46: H3 | B46: 47 | C46: MONTALUO | D46: JIMENEZ | E46: ERICK | F46: 33573989-2 | N46: 1 | O46: 1 | P46: 1 | Q46: 1 | R46: 1 | S46: 1 | T46: 1 | U46: 1 | V46: 1 | W46: 1 | X46: 1 | Y46: 1 | Z46: 1 | AA46: 1 | AL46: =SUM(G46:AK46) -> 14 | AM46: 32000 | AN46: =AM46*AL46 -> 448000
A47: H3 | B47: 47 | C47: URIBE | D47: VALENZUELA | E47: CARLOS | F47: 17209918-1 | S47: 1 | T47: 1 | U47: 1 | V47: 1 | W47: 1 | X47: 1 | Y47: 1 | Z47: 1 | AA47: 1 | AB47: 1 | AC47: 1 | AD47: 1 | AE47: 1 | AL47: =SUM(G47:AK47) -> 13 | AM47: 32000 | AN47: =AM47*AL47 -> 416000
...

Sheet ACONCAGUA
A6: CORRELATIVO N°2 | G6: 45778 | H6: 45779 | I6: 45780 | J6: 45781 | K6: 45782 | L6: 45783 | M6: 45784 | N6: 45785 | O6: 45786 | P6: 45787 | Q6: 45788 | R6: 45789 | S6: 45790 | T6: 45791 | U6: 45792 | V6: 45793 | W6: 45794 | X6: 45795 | Y6: 45796 | Z6: 45797 | AA6: 45798 | AB6: 45799 | AC6: 45800 | AD6: 45801 | AE6: 45802 | AF6: 45803 | AG6: 45804 | AH6: 45805 | AI6: 45806 | AJ6: 45807 | AK6: 45808 | AL6: 01 AL 31 DE MAYO
B9: HAB | C9: APELLIDO PATERNO | D9: APELLIDO MATERNO | E9: NOMBRE | F9: RUT | AL9: D. OCUP | AM9: V. OCUP | AN9: T. OCUP.
A10: AC | B10: 205 | C10: CUETO | E10: SUSUNA | F10: 13225829-5 | G10: 1 | H10: 1 | I10: 1 | J10: 1 | K10: 1 | L10: 1 | AL10: =SUM(G10:AK10) -> 6 | AM10: 33000 | AN10: =AM10*AL10 -> 198000
A11: AC | B11: 205 | C11: RIVERA | E11: DANIELA | F11: 18024668-1 | G11: 1 | H11: 1 | I11: 1 | J11: 1 | K11: 1 | L11: 1 | AL11: =SUM(G11:AK11) -> 6 | AM11: 33000 | AN11: =AM11*AL11 -> 198000
A12: AC | B12: 302 | C12: SANDOVAL | E12: GISELA | F12: 19120950-8 | G12: 1 | H12: 1 | I12: 1 | J12: 1 | K12: 1 | L12: 1 | AL12: =SUM(G12:AK12) -> 6 | AM12: 33000 | AN12: =AM12*AL12 -> 198000
A13: AC | B13: 302 | C13: PINOCHET | D13: RETAMAL | E13: CONSUELO | F13: 17904147-2 | G13: 1 | H13: 1 | I13: 1 | J13: 1 | K13: 1 | L13: 1 | AL13: =SUM(G13:AK13) -> 6 | AM13: 33000 | AN13: =AM13*AL13 -> 198000
A14: AC | B14: 401 | C14: ALTAMIRANO | E14: JUAN | F14: 11960350-1 | G14: 1 | AL14: =SUM(G14:AK14) -> 1 | AM14: 60000 | AN14: =AM14*AL14 -> 60000
A15: AC | B15: 401 | C15: RODRIGUEZ | D15: CARRASCO | E15: PABLO | F15: 18709818-1 | H15: 1 | I15: 1 | AL15: =SUM(G15:AK15) -> 2 | AM15: 33000 | AN15: =AM15*AL15 -> 66000
A16: AC | B16: 401 | C16: ARROYO | E16: PATRICIO | F16: 14472229-9 | H16: 1 | I16: 1 | AL16: =SUM(G16:AK16) -> 2 | AM16: 33000 | AN16: =AM16*AL16 -> 66000
A17: AC | B17: 401 | C17: ALTAMIRANO | E17: JUAN | F17: 11960350-1 | K17: 1 | L17: 1 | AL17: =SUM(G17:AK17) -> 2 | AM17: 33000 | AN17: =AM17*AL17 -> 66000
A18: AC | B18: 401 | C18: AGUILERA | E18: JORGE | F18: 19122318-7 | L18: 1 | AL18: =SUM(G18:AK18) -> 1 | AM18: 33000 | AN18: =AM18*AL18 -> 33000
A19: AC | B19: 404 | C19: ARROYO | E19: PATRICIO | F19: 14472229-9 | G19: 1 | J19: 1 | K19: 1 | L19: 1 | AL19: =SUM(G19:AK19) -> 4 | AM19: 33000 | AN19: =AM19*AL19 -> 132000
A20: AC | B20: 404 | C20: GUTIERREZ | E20: JUAN | F20: 17211423-7 | G20: 1 | H20: 1 | I20: 1 | J20: 1 | K20: 1 | L20: 1 | AL20: =SUM(G20:AK20) -> 6 | AM20: 33000 | AN20: =AM20*AL20 -> 198000
A21: AC | B21: 404 | C21: SEPULVEDA | E21: GONZALO | F21: 18408247-0 | H21: 1 | I21: 1 | AL21: =SUM(G21:AK21) -> 2 | AM21: 33000 | AN21: =AM21*AL21 -> 66000
A22: AC | B22: 406 | C22: SOTO | D22: HERRERA | E22: MARIA | F22: 19797369-2 | J22: 1 | K22: 1 | L22: 1 | AL22: =SUM(G22:AK22) -> 3 | AM22: 60000 | AN22: =AM22*AL22 -> 180000
A23: AC | B23: 507 | C23: COVARRUBIA | E23: JAVIERA | F23: 17353868-5 | G23: 1 | AL23: =SUM(G23:AK23) -> 1 | AM23: 60000 | AN23: =AM23*AL23 -> 60000
A24: AC | B24: 604 | C24: COVARRUBIA | E24: JAVIERA | F24: 17353868-5 | H24: 1 | I24: 1 | J24: 1 | K24: 1 | L24: 1 | AL24: =SUM(G24:AK24) -> 5 | AM24: 33000 | AN24: =AM24*AL24 -> 165000
A25: AC | B25: 604 | C25: TOLOZA | D25: ARROYO | E25: KATHERINE | F25: 15188041-K | H25: 1 | I25: 1 | J25: 1 | K25: 1 | L25: 1 | AL25: =SUM(G25:AK25) -> 5 | AM25: 33000 | AN25: =AM25*AL25 -> 165000
A26: AC | B26: 903 | C26: OLIVARES | D26: MIGUELES | E26: GONZALO | F26: 18843149-6 | G26: 1 | H26: 1 | I26: 1 | J26: 1 | K26: 1 | L26: 1 | AL26: =SUM(G26:AK26) -> 6 | AM26: 33000 | AN26: =AM26*AL26 -> 198000
A27: AC | B27: 903 | C27: MOSCOSO | E27: DANIEL | F27: 17678108-4 | G27: 1 | H27: 1 | I27: 1 | J27: 1 | K27: 1 | L27: 1 | AL27: =SUM(G27:AK27) -> 6 | AM27: 33000 | AN27: =AM27*AL27 -> 198000
A28: AC | B28: 1101 | C28: SEPULVEDA | E28: FERNANDO | F28: 17319810-8 | G28: 1 | H28: 1 | I28: 1 | J28: 1 | K28: 1 | L28: 1 | AL28: =SUM(G28:AK28) -> 6 | AM28: 33000 | AN28: =AM28*AL28 -> 198000
A29: AC | B29: 1101 | C29: AMESTICA | E29: JORGE | F29: 19720960-7 | G29: 1 | H29: 1 | I29: 1 | J29: 1 | K29: 1 | L29: 1 | AL29: =SUM(G29:AK29) -> 6 | AM29: 33000 | AN29: =AM29*AL29 -> 198000
A30: AC | B30: 1402 | C30: QUEVEDO | E30: CRISTOBAL | F30: 19359014-4 | G30: 1 | H30: 1 | I30: 1 | J30: 1 | K30: 1 | L30: 1 | AL30: =SUM(G30:AK30) -> 6 | AM30: 33000 | AN30: =AM30*AL30 -> 198000
A31: AC | B31: 1402 | C31: AGUILERA | E31: JORGE | F31: 19122318-7 | G31: 1 | H31: 1 | I31: 1 | AL31: =SUM(G31:AK31) -> 3 | AM31: 33000 | AN31: =AM31*AL31 -> 99000
A32: AC | B32: 1304 | C32: RODRIGUEZ | D32: CARRASCO | E32: PABLO | F32: 18709818-1 | G32: 1 | AL32: =SUM(G32:AK32) -> 1 | AM32: 33000 | AN32: =AM32*AL32 -> 33000
A33: AC | B33: 403 | C33: TOLOSA | D33: ARROYO | E33: KATHERINE | F33: 15188041-K | G33: 1 | AL33: =SUM(G33:AK33) -> 1 | AM33: 33000 | AN33: =AM33*AL33 -> 33000
A34: AC | B34: 205 | C34: PEREZ | E34: MARIA F | F34: 18785701-5 | M34: 1 | N34: 1 | O34: 1 | P34: 1 | Q34: 1 | R34: 1 | S34: 1 | AL34: =SUM(G34:AK34) -> 7 | AM34: 33000 | AN34: =AM34*AL34 -> 231000
A35: AC | B35: 205 | C35: CERECEDA | E35: SOLANGE | F35: 17172403-1 | M35: 1 | N35: 1 | O35: 1 | P35: 1 | Q35: 1 | R35: 1 | S35: 1 | AL35: =SUM(G35:AK35) -> 7 | AM35: 33000 | AN35: =AM35*AL35 -> 231000
A36: AC | B36: 302 | C36: BERNARD | E36: FERNANDO | F36: 17137085-K | M36: 1 | N36: 1 | O36: 1 | P36: 1 | Q36: 1 | R36: 1 | S36: 1 | AL36: =SUM(G36:AK36) -> 7 | AM36: 33000 | AN36: =AM36*AL36 -> 231000
A37: AC | B37: 302 | C37: ARCHILES | E37: FELIX | F37: 17137111-2 | M37: 1 | N37: 1 | O37: 1 | P37: 1 | Q37: 1 | R37: 1 | S37: 1 | AL37: =SUM(G37:AK37) -> 7 | AM37: 33000 | AN37: =AM37*AL37 -> 231000
A38: AC | B38: 401 | C38: ALTAMIRANO | E38: JUAN | F38: 11960350-1 | M38: 1 | AL38: =SUM(G38:AK38) -> 1 | AM38: 33000 | AN38: =AM38*AL38 -> 33000
A39: AC | B39: 401 | C39: AGUILERA | E39: JORGE | F39: 19122318-7 | M39: 1 | AL39: =SUM(G39:AK39) -> 1 | AM39: 33000 | AN39: =AM39*AL39 -> 33000
A40: AC | B40: 404 | C40: ARROYO | E40: PATRICIO | F40: 14472229-9 | M40: 1 | N40: 1 | O40: 1 | P40: 1 | Q40: 1 | R40: 1 | S40: 1 | AL40: =SUM(G40:AK40) -> 7 | AM40: 33000 | AN40: =AM40*AL40 -> 231000
A41: AC | B41: 404 | C41: AZOCAR | D41: CORNEJO | E41: NICOLAS | F41: 19114498-8 | M41: 1 | AL41: =SUM(G41:AK41) -> 1 | AM41: 33000 | AN41: =AM41*AL41 -> 33000
A42: AC | B42: 404 | C42: SEPULVEDA | E42: GONZALO | F42: 18408247-0 | N42: 1 | O42: 1 | P42: 1 | Q42: 1 | R42: 1 | S42: 1 | AL42: =SUM(G42:AK42) -> 6 | AM42: 33000 | AN42: =AM42*AL42 -> 198000
A43: AC | B43: 406 | C43: SOTO | D43: HERRERA | E43: MARIA | F43: 19797369-2 | M43: 1 | AL43: =SUM(G43:AK43) -> 1 | AM43: 60000 | AN43: =AM43*AL43 -> 60000
A44: AC | B44: 604 | C44: TOLOZA | E44: KATHERINE | F44: 15188041-1 | M44: 1 | AL44: =SUM(G44:AK44) -> 1 | AM44: 33000 | AN44: =AM44*AL44 -> 33000
A45: AC | B45: 604 | C45: AZOCAR | D45: CORNEJO | E45: NICOLAS | F45: 19114498-8 | N45: 1 | O45: 1 | P45: 1 | Q45: 1 | R45: 1 | S45: 1 | AL45: =SUM(G45:AK45) -> 6 | AM45: 33000 | AN45: =AM45*AL45 -> 198000
A46: AC | B46: 604 | C46: AGUILERA | E46: JORGE | F46: 19122318-7 | N46: 1 | O46: 1 | P46: 1 | Q46: 1 | R46: 1 | S46: 1 | AL46: =SUM(G46:AK46) -> 6 | AM46: 33000 | AN46: =AM46*AL46 -> 198000
A47: AC | B47: 903 | C47: CARRASCO | E47: FELIPE | F47: 16690731-4 | M47: 1 | N47: 1 | O47: 1 | P47: 1 | Q47: 1 | R47: 1 | S47: 1 | AL47: =SUM(G47:AK47) -> 7 | AM47: 33000 | AN47: =AM47*AL47 -> 231000
...
