Workbook

Sheet H1
A6: CORRELATIVO N°4 | G6: 45839 | H6: 45840 | I6: 45841 | J6: 45842 | K6: 45843 | L6: 45844 | M6: 45845 | N6: 45846 | O6: 45847 | P6: 45848 | Q6: 45849 | R6: 45850 | S6: 45851 | T6: 45852 | U6: 45853 | V6: 45854 | W6: 45855 | X6: 45856 | Y6: 45857 | Z6: 45858 | AA6: 45859 | AB6: 45860 | AC6: 45861 | AD6: 45862 | AE6: 45863 | AF6: 45864 | AG6: 45865 | AH6: 45866 | AI6: 45867 | AJ6: 45868 | AK6: 45869 | AL6: 01 AL 31 DE JULIO
B9: HAB | C9: APELLIDO PATERNO | D9: APELLIDO MATERNO | E9: NOMBRE | F9: RUT | AL9: D. OCUP | AM9: V. OCUP | AN9: T. OCUP.
A10: H1 | B10: 3 | C10: RIOS | D10: TOLOZA | E10: ELIAS | F10: 20356924-6 | G10: 1 | AL10: =SUM(G10:AK10) -> 1 | AM10: 32000 | AN10: =AM10*AL10 -> 32000
A11: H1 | B11: 3 | C11: DIAZ | D11: SAEZ | E11: PATRICIO | F11: 20660891-9 | G11: 1 | AL11: =SUM(G11:AK11) -> 1 | AM11: 32000 | AN11: =AM11*AL11 -> 32000
A12: H1 | B12: 5 | C12: VIEDMA | D12: CASTILLO | E12: JORGE | F12: 11183349-4 | G12: 1 | AL12: =SUM(G12:AK12) -> 1 | AM12: 32000 | AN12: =AM12*AL12 -> 32000
A13: H1 | B13: 5 | C13: MANRIQUEZ | D13: BUSTAMANTE | E13: LUCAS | F13: 11295257-8 | G13: 1 | AL13: =SUM(G13:AK13) -> 1 | AM13: 32000 | AN13: =AM13*AL13 -> 32000
A14: H1 | B14: 7 | C14: JARAMILLO | D14: PAINEQUIR | E14: MARIO | F14: 10351151-8 | G14: 1 | AL14: =SUM(G14:AK14) -> 1 | AM14: 32000 | AN14: =AM14*AL14 -> 32000
A15: H1 | B15: 7 | C15: ULLOA | D15: NECULMAN | E15: DANIEL | F15: 17814175-9 | G15: 1 | AL15: =SUM(G15:AK15) -> 1 | AM15: 32000 | AN15: =AM15*AL15 -> 32000
A16: H1 | B16: 8 | C16: CARO | D16: CONTRERAS | E16: JOSE | F16: 12051577-2 | G16: 1 | AL16: =SUM(G16:AK16) -> 1 | AM16: 32000 | AN16: =AM16*AL16 -> 32000
A17: H1 | B17: 8 | C17: GONZALES | D17: SANGUINETTI | E17: MATIAS | F17: 21269464-9 | G17: 1 | AL17: =SUM(G17:AK17) -> 1 | AM17: 32000 | AN17: =AM17*AL17 -> 32000
A18: H1 | B18: 9 | C18: HERNANDEZ | D18: ARANGUIZ | E18: JUAN | F18: 13316376-K | G18: 1 | AL18: =SUM(G18:AK18) -> 1 | AM18: 32000 | AN18: =AM18*AL18 -> 32000
A19: H1 | B19: 9 | C19: ESPINOZA | D19: TRONCOSO | E19: MARCO | F19: 15499412-2 | G19: 1 | AL19: =SUM(G19:AK19) -> 1 | AM19: 32000 | AN19: =AM19*AL19 -> 32000
A20: H1 | B20: 10 | C20: INOSTROZA | D20: INOSTROZA | E20: RINDOLFO | F20: 11585182-9 | G20: 1 | AL20: =SUM(G20:AK20) -> 1 | AM20: 32000 | AN20: =AM20*AL20 -> 32000
A21: H1 | B21: 10 | C21: PICHON | D21: CORNEJO | E21: MARCO | F21: 12915179-K | G21: 1 | AL21: =SUM(G21:AK21) -> 1 | AM21: 32000 | AN21: =AM21*AL21 -> 32000
... A146: H1 | B146: 120 | C146: GONZALEZ | D146: ROJAS | E146: PATRICIO | F146: 15330424-6 | G146: 1 | AL146: =SUM(G146:AK146) -> 1 | AM146: 32000 | AN146: =AM146*AL146 -> 32000
A147: H1 | B147: 12B | C147: IMIHUALA | D147: COLLILEF | E147: ELIAS | F147: 19553112-9 | G147: 1 | AL147: =SUM(G147:AK147) -> 1 | AM147: 32000 | AN147: =AM147*AL147 -> 32000
A148: H1 | B148: 12B | C148: HUIRCAPAN | D148: RUCAN | E148: JOSE | F148: 10332868-3 | G148: 1 | AL148: =SUM(G148:AK148) -> 1 | AM148: 32000 | AN148: =AM148*AL148 -> 32000
A149: H1 | B149: 21B | C149: BRAVO | D149: MORA | E149: CLAUDIO | F149: 18111892-K | G149: 1 | AL149: =SUM(G149:AK149) -> 1 | AM149: 32000 | AN149: =AM149*AL149 -> 32000
A150: H1 | B150: 26B | C150: BUSTOS | D150: SALAZAR | E150: FRANK | F150: 20364247-4 | G150: 1 | AL150: =SUM(G150:AK150) -> 1 | AM150: 32000 | AN150: =AM150*AL150 -> 32000
A151: H1 | B151: 26B | C151: PARRA | D151: VILLEGAS | E151: ALEXIS | F151: 14273288-2 | G151: 1 | AL151: =SUM(G151:AK151) -> 1 | AM151: 32000 | AN151: =AM151*AL151 -> 32000
A152: H1 | B152: 42B | C152: ARRIAGADA | D152: OGEDA | E152: AUGUSTO | F152: 20839872-2 | G152: 1 | AL152: =SUM(G152:AK152) -> 1 | AM152: 32000 | AN152: =AM152*AL152 -> 32000
A153: H1 | B153: 42B | C153: CAMPOS | D153: HENRRIQUEZ | E153: MIGUEL | F153: 19194420-4 | G153: 1 | AL153: =SUM(G153:AK153) -> 1 | AM153: 32000 | AN153: =AM153*AL153 -> 32000
A154: H1 | B154: 43B | C154: CARCAMO | D154: GONZALES | E154: JEAN | F154: 19654042-3 | G154: 1 | AL154: =SUM(G154:AK154) -> 1 | AM154: 32000 | AN154: =AM154*AL154 -> 32000
A155: H1 | B155: 43B | C155: VIDAL | D155: VALENZUELA | E155: JACINTO | F155: 16825187-3 | G155: 1 | AL155: =SUM(G155:AK155) -> 1 | AM155: 32000 | AN155: =AM155*AL155 -> 32000
A156: H1 | B156: 44B | C156: REYES | D156: LUCERO | E156: ANDERSON | F156: 15872186-4 | G156: 1 | AL156: =SUM(G156:AK156) -> 1 | AM156: 32000 | AN156: =AM156*AL156 -> 32000
A157: H1 | B157: 44B | C157: VENEGAS | D157: GARCES | E157: HERNAN | F157: 16641048-7 | G157: 1 | AL157: =SUM(G157:AK157) -> 1 | AM157: 32000 | AN157: =AM157*AL157 -> 32000
A158: H1 | B158: 3B | C158: ARCHILES | D158: SALVO | E158: FELIX | F158: 17137111-2 | G158: 1 | AL158: =SUM(G158:AK158) -> 1 | AM158: 32000 | AN158: =AM158*AL158 -> 32000
... A173: H1 | B173: 18B | C173: FLORES | D173: BAUTISTA | E173: MILENA | F173: 18579932-8 | G173: 1 | AL173: =SUM(G173:AK173) -> 1 | AM173: 32000 | AN173: =AM173*AL173 -> 32000
A174: H1 | B174: 3 | C174: MORAGA | D174: POBLETE | E174: IGNACIO | F174: 19777682-K | H174: 1 | I174: 1 | J174: 1 | K174: 1 | L174: 1 | M174: 1 | N174: 1 | O174: 1 | P174: 1 | Q174: 1 | R174: 1 | S174: 1 | T174: 1 | U174: 1 | AL174: =SUM(G174:AK174) -> 14 | AM174: 32000 | AN174: =AM174*AL174 -> 448000
A175: H1 | B175: 3 | C175: ORTIZ | D175: SANTELICES | E175: ALEJANDRO | F175: 13856349-9 | H175: 1 | I175: 1 | J175: 1 | K175: 1 | L175: 1 | M175: 1 | N175: 1 | O175: 1 | P175: 1 | Q175: 1 | R175: 1 | S175: 1 | T175: 1 | U175: 1 | AL175: =SUM(G175:AK175) -> 14 | AM175: 32000 | AN175: =AM175*AL175 -> 448000
A176: H1 | B176: 4 | C176: CARO | D176: CONTRERAS | E176: JOSE | F176: 12051577-2 | H176: 1 | I176: 1 | J176: 1 | K176: 1 | L176: 1 | M176: 1 | N176: 1 | O176: 1 | AL176: =SUM(G176:AK176) -> 8 | AM176: 32000 | AN176: =AM176*AL176 -> 256000
A177: H1 | B177: 4 | C177: GONZALES | D177: SANGUINETTI | E177: MATIAS | F177: 21269464-9 | H177: 1 | I177: 1 | J177: 1 | K177: 1 | L177: 1 | M177: 1 | N177: 1 | O177: 1 | AL177: =SUM(G177:AK177) -> 8 | AM177: 32000 | AN177: =AM177*AL177 -> 256000
A178: H1 | B178: 5 | C178: MANRIQUEZ | D178: BUSTAMANTE | E178: LUCAS | F178: 11295257-8 | J178: 1 | K178: 1 | L178: 1 | AL178: =SUM(G178:AK178) -> 3 | AM178: 32000 | AN178: =AM178*AL178 -> 96000
A179: H1 | B179: 5 | C179: VIEDMA | D179: CASTILLO | E179: JORGE | F179: 11183349-4 | J179: 1 | K179: 1 | L179: 1 | AL179: =SUM(G179:AK179) -> 3 | AM179: 32000 | AN179: =AM179*AL179 -> 96000
A180: H1 | B180: 7 | C180: NUÑEZ | D180: SEPULVEDA | E180: CRISTOFER | F180: 15568474-7 | H180: 1 | I180: 1 | J180: 1 | K180: 1 | L180: 1 | M180: 1 | N180: 1 | O180: 1 | P180: 1 | Q180: 1 | R180: 1 | S180: 1 | T180: 1 | U180: 1 | AL180: =SUM(G180:AK180) -> 14 | AM180: 32000 | AN180: =AM180*AL180 -> 448000
A181: H1 | B181: 7 | C181: SALGADO | D181: GAETE | E181: DANIEL | F181: 18233824-9 | H181: 1 | I181: 1 | J181: 1 | K181: 1 | L181: 1 | M181: 1 | N181: 1 | O181: 1 | P181: 1 | Q181: 1 | R181: 1 | S181: 1 | T181: 1 | U181: 1 | AL181: =SUM(G181:AK181) -> 14 | AM181: 32000 | AN181: =AM181*AL181 -> 448000
A182: H1 | B182: 8 | C182: GONZALEZ | D182: HENRIQUEZ | E182: JORGE | F182: 13025138-2 | O182: 1 | P182: 1 | Q182: 1 | R182: 1 | S182: 1 | T182: 1 | U182: 1 | AL182: =SUM(G182:AK182) -> 7 | AM182: 32000 | AN182: =AM182*AL182 -> 224000
A183: H1 | B183: 8 | C183: BARRA | D183: NAVEA | E183: DANIEL | F183: 12188198-5 | O183: 1 | P183: 1 | Q183: 1 | R183: 1 | S183: 1 | T183: 1 | U183: 1 | AL183: =SUM(G183:AK183) -> 7 | AM183: 32000 | AN183: =AM183*AL183 -> 224000
A184: H1 | B184: 9 | C184: AMPUERO | D184: MALDONADO | E184: JUAN | F184: 7910608-9 | H184: 1 | I184: 1 | J184: 1 | K184: 1 | L184: 1 | M184: 1 | N184: 1 | O184: 1 | P184: 1 | Q184: 1 | R184: 1 | S184: 1 | T184: 1 | U184: 1 | AL184: =SUM(G184:AK184) -> 14 | AM184: 32000 | AN184: =AM184*AL184 -> 448000
A185: H1 | B185: 9 | C185: ESPINOZA | D185: TRONCOSO | E185: MARCO | F185: 15499412-2 | H185: 1 | I185: 1 | J185: 1 | K185: 1 | AL185: =SUM(G185:AK185) -> 4 | AM185: 32000 | AN185: =AM185*AL185 -> 128000
...

Sheet H3
A6: CORRELATIVO N°4 | G6: 45839 | H6: 45840 | I6: 45841 | J6: 45842 | K6: 45843 | L6: 45844 | M6: 45845 | N6: 45846 | O6: 45847 | P6: 45848 | Q6: 45849 | R6: 45850 | S6: 45851 | T6: 45852 | U6: 45853 | V6: 45854 | W6: 45855 | X6: 45856 | Y6: 45857 | Z6: 45858 | AA6: 45859 | AB6: 45860 | AC6: 45861 | AD6: 45862 | AE6: 45863 | AF6: 45864 | AG6: 45865 | AH6: 45866 | AI6: 45867 | AJ6: 45868 | AK6: 45869 | AL6: 01 AL 31 DE JULIO
B9: HAB | C9: APELLIDO PATERNO | D9: APELLIDO MATERNO | E9: NOMBRE | F9: RUT | AL9: D. OCUP | AM9: V. OCUP | AN9: T. OCUP.
A10: H3 | B10: 1 | C10: DIAZ | D10: PUGA | E10: GUILLERMO | F10: 12789118-4 | G10: 1 | AL10: =SUM(G10:AK10) -> 1 | AM10: 32000 | AN10: =AM10*AL10 -> 32000
A11: H3 | B11: 1 | C11: TAPIA | D11: PAZ | E11: JUAN | F11: 12963938-5 | G11: 1 | AL11: =SUM(G11:AK11) -> 1 | AM11: 32000 | AN11: =AM11*AL11 -> 32000
A12: H3 | B12: 2 | C12: FIGUEROA | D12: QUEZADA | E12: CARLOS | F12: 9299666-2 | G12: 1 | AL12: =SUM(G12:AK12) -> 1 | AM12: 32000 | AN12: =AM12*AL12 -> 32000
A13: H3 | B13: 2 | C13: PARRA | D13: PUGA | E13: JORGE | F13: 15569834-9 | G13: 1 | AL13: =SUM(G13:AK13) -> 1 | AM13: 32000 | AN13: =AM13*AL13 -> 32000
A14: H3 | B14: 11 | C14: JARA | D14: FUENTES | E14: RICARDO | F14: 15188863-1 | G14: 1 | AL14: =SUM(G14:AK14) -> 1 | AM14: 32000 | AN14: =AM14*AL14 -> 32000
A15: H3 | B15: 11 | C15: CONTRERAS | D15: POLANCO | E15: JORGE | F15: 17287619-6 | G15: 1 | AL15: =SUM(G15:AK15) -> 1 | AM15: 32000 | AN15: =AM15*AL15 -> 32000
A16: H3 | B16: 12 | C16: DAZA | D16: CASTILLO | E16: CARLOS | F16: 13725970-2 | G16: 1 | AL16: =SUM(G16:AK16) -> 1 | AM16: 32000 | AN16: =AM16*AL16 -> 32000
A17: H3 | B17: 13 | C17: AGUAYO | D17: RODRIGUEZ | E17: JAIME | F17: 10073590-3 | G17: 1 | AL17: =SUM(G17:AK17) -> 1 | AM17: 32000 | AN17: =AM17*AL17 -> 32000
A18: H3 | B18: 13 | C18: AGUILERA | D18: BRAVO | E18: MARIO | F18: 16765205-0 | G18: 1 | AL18: =SUM(G18:AK18) -> 1 | AM18: 32000 | AN18: =AM18*AL18 -> 32000
A19: H3 | B19: 15 | C19: JARA | D19: VASQUEZ | E19: RODOLFO | F19: 20611553-K | G19: 1 | AL19: =SUM(G19:AK19) -> 1 | AM19: 32000 | AN19: =AM19*AL19 -> 32000
A20: H3 | B20: 15 | C20: LANAS | D20: VALDENEGRO | E20: CRISTIAN | F20: 18037466-3 | G20: 1 | AL20: =SUM(G20:AK20) -> 1 | AM20: 32000 | AN20: =AM20*AL20 -> 32000
A21: H3 | B21: 17 | C21: FIERRO | D21: DURAN | E21: DAVID | F21: 18810893-8 | G21: 1 | AL21: =SUM(G21:AK21) -> 1 | AM21: 32000 | AN21: =AM21*AL21 -> 32000
... A37: H3 | B37: 90 | C37: CANALES | D37: LAGOS | E37: MATIAS | F37: 21830481-8 | G37: 1 | AL37: =SUM(G37:AK37) -> 1 | AM37: 32000 | AN37: =AM37*AL37 -> 32000
A38: H3 | B38: 0 | C38: ADAMAS | D38: REYES | E38: BRAYAN | F38: 17219265-3 | H38: 1 | I38: 1 | J38: 1 | K38: 1 | L38: 1 | M38: 1 | N38: 1 | O38: 1 | P38: 1 | Q38: 1 | R38: 1 | S38: 1 | T38: 1 | U38: 1 | AL38: =SUM(G38:AK38) -> 14 | AM38: 32000 | AN38: =AM38*AL38 -> 448000
A39: H3 | B39: 0 | C39: ALVAREZ | D39: ADASMA | E39: IGNACIO | F39: 20924569-8 | H39: 1 | I39: 1 | J39: 1 | K39: 1 | L39: 1 | M39: 1 | N39: 1 | O39: 1 | P39: 1 | Q39: 1 | R39: 1 | S39: 1 | T39: 1 | U39: 1 | AL39: =SUM(G39:AK39) -> 14 | AM39: 32000 | AN39: =AM39*AL39 -> 448000
A40: H3 | B40: 1 | C40: ESCOBAR | D40: ARRIAGADA | E40: PATRICIO | F40: 18405090-0 | H40: 1 | I40: 1 | J40: 1 | K40: 1 | L40: 1 | M40: 1 | N40: 1 | O40: 1 | P40: 1 | Q40: 1 | R40: 1 | S40: 1 | T40: 1 | U40: 1 | AL40: =SUM(G40:AK40) -> 14 | AM40: 32000 | AN40: =AM40*AL40 -> 448000
A41: H3 | B41: 2 | C41: ADAMAS | D41: REYES | E41: FERNANDO | F41: 16541548-5 | H41: 1 | I41: 1 | J41: 1 | K41: 1 | L41: 1 | M41: 1 | N41: 1 | O41: 1 | P41: 1 | Q41: 1 | R41: 1 | S41: 1 | T41: 1 | U41: 1 | AL41: =SUM(G41:AK41) -> 14 | AM41: 32000 | AN41: =AM41*AL41 -> 448000
A42: H3 | B42: 2 | C42: RUIZ | D42: MANRIQUEZ | E42: ERMES | F42: 15209490-6 | H42: 1 | I42: 1 | J42: 1 | K42: 1 | L42: 1 | M42: 1 | N42: 1 | O42: 1 | P42: 1 | Q42: 1 | R42: 1 | S42: 1 | T42: 1 | U42: 1 | AL42: =SUM(G42:AK42) -> 14 | AM42: 32000 | AN42: =AM42*AL42 -> 448000
A43: H3 | B43: 3 | C43: CONSUEGRA | D43: ARCE | E43: WILLUIAM | F43: 26341309-1 | H43: 1 | I43: 1 | J43: 1 | K43: 1 | L43: 1 | M43: 1 | N43: 1 | O43: 1 | P43: 1 | Q43: 1 | R43: 1 | S43: 1 | T43: 1 | U43: 1 | AL43: =SUM(G43:AK43) -> 14 | AM43: 32000 | AN43: =AM43*AL43 -> 448000
A44: H3 | B44: 3 | C44: LIGNAI | D44: TRUJILLO | E44: LUIS | F44: 10516209-K | H44: 1 | I44: 1 | J44: 1 | K44: 1 | L44: 1 | M44: 1 | N44: 1 | O44: 1 | P44: 1 | Q44: 1 | R44: 1 | S44: 1 | T44: 1 | U44: 1 | AL44: =SUM(G44:AK44) -> 14 | AM44: 32000 | AN44: =AM44*AL44 -> 448000
A45: H3 | B45: 6 | C45: HINOTROZA | D45: ARAUJO | E45: JOSE | F45: 450991894 | H45: 1 | I45: 1 | J45: 1 | K45: 1 | L45: 1 | M45: 1 | N45: 1 | O45: 1 | P45: 1 | Q45: 1 | R45: 1 | S45: 1 | T45: 1 | U45: 1 | AL45: =SUM(G45:AK45) -> 14 | AM45: 32000 | AN45: =AM45*AL45 -> 448000
A46: H3 | B46: 10 | C46: BRIONES | D46: LEAL | E46: MANUEL | F46: 13281520-8 | H46: 1 | I46: 1 | J46: 1 | K46: 1 | L46: 1 | M46: 1 | N46: 1 | O46: 1 | P46: 1 | Q46: 1 | R46: 1 | S46: 1 | T46: 1 | U46: 1 | AL46: =SUM(G46:AK46) -> 14 | AM46: 32000 | AN46: =AM46*AL46 -> 448000
A47: H3 | B47: 10 | C47: DOMINGUEZ | D47: SALAZAR | E47: JUAN | F47: 12925017-8 | H47: 1 | I47: 1 | J47: 1 | K47: 1 | L47: 1 | M47: 1 | N47: 1 | O47: 1 | P47: 1 | Q47: 1 | R47: 1 | S47: 1 | T47: 1 | U47: 1 | AL47: =SUM(G47:AK47) -> 14 | AM47: 32000 | AN47: =AM47*AL47 -> 448000
A48: H3 | B48: 11 | C48: BEROIZA | D48: RAILAF | E48: NICOLAS | F48: 19463033-6 | H48: 1 | I48: 1 | J48: 1 | K48: 1 | L48: 1 | M48: 1 | N48: 1 | O48: 1 | P48: 1 | Q48: 1 | R48: 1 | S48: 1 | T48: 1 | U48: 1 | AL48: =SUM(G48:AK48) -> 14 | AM48: 32000 | AN48: =AM48*AL48 -> 448000
A49: H3 | B49: 11 | C49: RIQUELME | D49: CASTILLO | E49: AROLDO | F49: 13623789-6 | H49: 1 | I49: 1 | J49: 1 | K49: 1 | L49: 1 | M49: 1 | N49: 1 | O49: 1 | P49: 1 | Q49: 1 | R49: 1 | S49: 1 | T49: 1 | U49: 1 | AL49: =SUM(G49:AK49) -> 14 | AM49: 32000 | AN49: =AM49*AL49 -> 448000
A50: H3 | B50: 12 | C50: COLLARTE | D50: VASQUEZ | E50: ARIEL | F50: 18070686-0 | H50: 1 | I50: 1 | J50: 1 | K50: 1 | L50: 1 | M50: 1 | N50: 1 | O50: 1 | P50: 1 | Q50: 1 | R50: 1 | S50: 1 | T50: 1 | U50: 1 | AL50: =SUM(G50:AK50) -> 14 | AM50: 32000 | AN50: =AM50*AL50 -> 448000
A51: H3 | B51: 12 | C51: FLORES | D51: MARDONES | E51: CESAR | F51: 20439946-8 | H51: 1 | I51: 1 | J51: 1 | K51: 1 | L51: 1 | M51: 1 | N51: 1 | O51: 1 | P51: 1 | Q51: 1 | R51: 1 | S51: 1 | T51: 1 | U51: 1 | AL51: =SUM(G51:AK51) -> 14 | AM51: 32000 | AN51: =AM51*AL51 -> 448000
A52: H3 | B52: 13 | C52: VIVEROS | D52: AVILA | E52: CLAUDIO | F52: 17843247-8 | H52: 1 | I52: 1 | J52: 1 | K52: 1 | L52: 1 | M52: 1 | N52: 1 | O52: 1 | P52: 1 | Q52: 1 | R52: 1 | S52: 1 | T52: 1 | U52: 1 | AL52: =SUM(G52:AK52) -> 14 | AM52: 32000 | AN52: =AM52*AL52 -> 448000
A53: H3 | B53: 13 | C53: FUENTES | D53: CABRERA | E53: JAIME | F53: 14363777-8 | H53: 1 | I53: 1 | J53: 1 | K53: 1 | L53: 1 | M53: 1 | N53: 1 | O53: 1 | P53: 1 | Q53: 1 | R53: 1 | S53: 1 | T53: 1 | U53: 1 | AL53: =SUM(G53:AK53) -> 14 | AM53: 32000 | AN53: =AM53*AL53 -> 448000
A54: H3 | B54: 15 | C54: RETAMAL | D54: FUENTES | E54: PATRICIO | F54: 11904416-2 | H54: 1 | I54: 1 | J54: 1 | K54: 1 | L54: 1 | M54: 1 | N54: 1 | O54: 1 | P54: 1 | Q54: 1 | R54: 1 | S54: 1 | T54: 1 | U54: 1 | AL54: =SUM(G54:AK54) -> 14 | AM54: 32000 | AN54: =AM54*AL54 -> 448000
A55: H3 | B55: 17 | C55: JARA | D55: ZAPATA | E55: JUAN | F55: 14573834-2 | H55: 1 | I55: 1 | J55: 1 | K55: 1 | L55: 1 | M55: 1 | N55: 1 | O55: 1 | P55: 1 | Q55: 1 | R55: 1 | S55: 1 | T55: 1 | U55: 1 | AL55: =SUM(G55:AK55) -> 14 | AM55: 32000 | AN55: =AM55*AL55 -> 448000
A56: H3 | B56: 18 | C56: MEDINA | D56: SUAZO | E56: ANA | F56: 14070374-5 | H56: 1 | I56: 1 | J56: 1 | K56: 1 | L56: 1 | M56: 1 | N56: 1 | O56: 1 | P56: 1 | Q56: 1 | R56: 1 | S56: 1 | T56: 1 | U56: 1 | AL56: =SUM(G56:AK56) -> 14 | AM56: 32000 | AN56: =AM56*AL56 -> 448000
A57: H3 | B57: 19 | C57: CABRERA | D57: ALARCON | E57: ULICES | F57: 44484881-2 | J57: 1 | K57: 1 | L57: 1 | M57: 1 | N57: 1 | O57: 1 | P57: 1 | Q57: 1 | R57: 1 | S57: 1 | T57: 1 | U57: 1 | AL57: =SUM(G57:AK57) -> 12 | AM57: 32000 | AN57: =AM57*AL57 -> 384000
A58: H3 | B58: 19 | C58: GARCIA | D58: SAAVEDRA | E58: AMERICO | F58: 44484786-7 | J58: 1 | K58: 1 | L58: 1 | M58: 1 | N58: 1 | O58: 1 | P58: 1 | Q58: 1 | R58: 1 | S58: 1 | T58: 1 | U58: 1 | AL58: =SUM(G58:AK58) -> 12 | AM58: 32000 | AN58: =AM58*AL58 -> 384000
A59: H3 | B59: 24 | C59: ARENAS | D59: MANRIQUEZ | E59: DANIEL | F59: 11179233-K | H59: 1 | I59: 1 | J59: 1 | K59: 1 | L59: 1 | M59: 1 | N59: 1 | O59: 1 | P59: 1 | Q59: 1 | R59: 1 | S59: 1 | T59: 1 | U59: 1 | AL59: =SUM(G59:AK59) -> 14 | AM59: 32000 | AN59: =AM59*AL59 -> 448000
A60: H3 | B60: 24 | C60: TORRES | D60: BENITEZ | E60: ERIK | F60: 17870662-4 | H60: 1 | I60: 1 | J60: 1 | K60: 1 | L60: 1 | M60: 1 | N60: 1 | O60: 1 | P60: 1 | Q60: 1 | R60: 1 | S60: 1 | T60: 1 | U60: 1 | AL60: =SUM(G60:AK60) -> 14 | AM60: 32000 | AN60: =AM60*AL60 -> 448000
A61: H3 | B61: 26 | C61: ARAYA | D61: MARIN | E61: ISAAC | F61: 20167572-3 | H61: 1 | I61: 1 | J61: 1 | K61: 1 | L61: 1 | M61: 1 | N61: 1 | O61: 1 | P61: 1 | Q61: 1 | R61: 1 | S61: 1 | T61: 1 | U61: 1 | AL61: =SUM(G61:AK61) -> 14 | AM61: 32000 | AN61: =AM61*AL61 -> 448000
A62: H3 | B62: 26 | C62: CODERCH | D62: TORRES | E62: JOSE | F62: 20133484-5 | H62: 1 | I62: 1 | J62: 1 | K62: 1 | L62: 1 | M62: 1 | N62: 1 | O62: 1 | AL62: =SUM(G62:AK62) -> 8 | AM62: 32000 | AN62: =AM62*AL62 -> 256000
...

Sheet ACONCAGUA
A6: CORRELATIVO Nº4 | G6: 45839 | H6: 45840 | I6: 45841 | J6: 45842 | K6: 45843 | L6: 45844 | M6: 45845 | N6: 45846 | O6: 45847 | P6: 45848 | Q6: 45849 | R6: 45850 | S6: 45851 | T6: 45852 | U6: 45853 | V6: 45854 | W6: 45855 | X6: 45856 | Y6: 45857 | Z6: 45858 | AA6: 45859 | AB6: 45860 | AC6: 45861 | AD6: 45862 | AE6: 45863 | AF6: 45864 | AG6: 45865 | AH6: 45866 | AI6: 45867 | AJ6: 45868 | AK6: 45869 | AL6: 01 AL 31 DE JULIO
B9: HAB | C9: APELLIDO PATERNO | D9: APELLIDO MATERNO | E9: NOMBRE | F9: RUT | AL9: D. OCUP | AM9: V. OCUP | AN9: T. OCUP.
A10: AC | B10: 203 | C10: MOSCOSO | D10: SAEZ | E10: DANIEL | F10: 17678108-4 | G10: 1 | AL10: =SUM(G10:AK10) -> 1 | AM10: 33000 | AN10: =AM10*AL10 -> 33000
A11: AC | B11: 203 | C11: SEPULVEDA | D11: ABURTO | E11: FERNANDO | F11: 17319810-8 | G11: 1 | AL11: =SUM(G11:AK11) -> 1 | AM11: 33000 | AN11: =AM11*AL11 -> 33000
A12: AC | B12: 205 | C12: VELIS | D12: VARAS | E12: CLAUDIO | F12: 16728609-7 | G12: 1 | AL12: =SUM(G12:AK12) -> 1 | AM12: 33000 | AN12: =AM12*AL12 -> 33000
A13: AC | B13: 205 | C13: VALENZUELA | D13: NUÑEZ | E13: ESTEBAN | F13: 19408470-6 | G13: 1 | AL13: =SUM(G13:AK13) -> 1 | AM13: 33000 | AN13: =AM13*AL13 -> 33000
A14: AC | B14: 302 | C14: OLIVARES | D14: MIGUELES | E14: GONZALO | F14: 18843149-6 | G14: 1 | AL14: =SUM(G14:AK14) -> 1 | AM14: 33000 | AN14: =AM14*AL14 -> 33000
A15: AC | B15: 302 | C15: VILLARREAL | D15: CERNA | E15: EDWAR | F15: 20101406-9 | G15: 1 | AL15: =SUM(G15:AK15) -> 1 | AM15: 33000 | AN15: =AM15*AL15 -> 33000
A16: AC | B16: 304 | C16: CARRASCO | D16: AVILA | E16: CYNTHIA | F16: 19278457-3 | G16: 1 | AL16: =SUM(G16:AK16) -> 1 | AM16: 33000 | AN16: =AM16*AL16 -> 33000
A17: AC | B17: 304 | C17: TOLOZA | D17: ARROYO | E17: KATHERINE | F17: 15188041-K | G17: 1 | AL17: =SUM(G17:AK17) -> 1 | AM17: 33000 | AN17: =AM17*AL17 -> 33000
A18: AC | B18: 404 | C18: QUEVEDO | D18: MERINO | E18: CRISTÓBAL | F18: 19359014-4 | G18: 1 | AL18: =SUM(G18:AK18) -> 1 | AM18: 33000 | AN18: =AM18*AL18 -> 33000
A19: AC | B19: 404 | C19: AMESTICA | D19: HURVINA | E19: JORGE | F19: 19720960-7 | G19: 1 | AL19: =SUM(G19:AK19) -> 1 | AM19: 33000 | AN19: =AM19*AL19 -> 33000
A20: AC | B20: 604 | C20: GALAZ | D20: GONZALEZ | E20: ALEJANDRO | F20: 19527019-8 | G20: 1 | AL20: =SUM(G20:AK20) -> 1 | AM20: 33000 | AN20: =AM20*AL20 -> 33000
A21: AC | B21: 604 | C21: PINTO | D21: CHAVEZ | E21: CLAUDIO | F21: 13726534-6 | G21: 1 | AL21: =SUM(G21:AK21) -> 1 | AM21: 33000 | AN21: =AM21*AL21 -> 33000
... A27: AC | B27: 1302 | C27: DIAZ | D27: ZAMORANO | E27: VALENTINA | F27: 17764546-K | G27: 1 | AL27: =SUM(G27:AK27) -> 1 | AM27: 33000 | AN27: =AM27*AL27 -> 33000
A28: AC | B28: 1402 | C28: BRUNA | D28: ARAYA | E28: EDUARDO | F28: 16325978-8 | AL28: =SUM(G28:AK28) -> 0 | AM28: 33000 | AN28: =AM28*AL28 -> 0
A29: AC | B29: 1402 | C29: HERMOSILLA | D29: GUZMAN | E29: HECTOR | F29: 19297281-7 | G29: 1 | AL29: =SUM(G29:AK29) -> 1 | AM29: 33000 | AN29: =AM29*AL29 -> 33000
A30: AC | B30: 203 | C30: MOSCOSO | E30: DANIEL | F30: 17678108-4 | H30: 1 | M30: 1 | N30: 1 | AL30: =SUM(G30:AK30) -> 3 | AM30: 33000 | AN30: =AM30*AL30 -> 99000
A31: AC | B31: 203 | C31: VARAS | D31: CEPEDA | E31: BASTIAN | F31: 20779661-1 | H31: 1 | I31: 1 | J31: 1 | K31: 1 | L31: 1 | M31: 1 | N31: 1 | AL31: =SUM(G31:AK31) -> 7 | AM31: 33000 | AN31: =AM31*AL31 -> 231000
A32: AC | B32: 205 | C32: ZARATE | E32: FABIAN | F32: 18150201-0 | H32: 1 | I32: 1 | J32: 1 | K32: 1 | L32: 1 | M32: 1 | N32: 1 | AL32: =SUM(G32:AK32) -> 7 | AM32: 33000 | AN32: =AM32*AL32 -> 231000
A33: AC | B33: 205 | C33: SEPULVEDA | E33: GONZALO | F33: 18408247-0 | H33: 1 | I33: 1 | J33: 1 | K33: 1 | L33: 1 | M33: 1 | N33: 1 | AL33: =SUM(G33:AK33) -> 7 | AM33: 33000 | AN33: =AM33*AL33 -> 231000
A34: AC | B34: 302 | C34: BERNARD | E34: FERNANDO | F34: 17137085-K | H34: 1 | I34: 1 | J34: 1 | K34: 1 | L34: 1 | M34: 1 | N34: 1 | AL34: =SUM(G34:AK34) -> 7 | AM34: 33000 | AN34: =AM34*AL34 -> 231000
A35: AC | B35: 302 | C35: ARCHILES | E35: FELIX | F35: 17137111-2 | H35: 1 | I35: 1 | J35: 1 | K35: 1 | L35: 1 | M35: 1 | N35: 1 | AL35: =SUM(G35:AK35) -> 7 | AM35: 33000 | AN35: =AM35*AL35 -> 231000
A36: AC | B36: 304 | C36: AGUILERA | E36: JORGE | F36: 19122318-7 | H36: 1 | I36: 1 | J36: 1 | K36: 1 | L36: 1 | M36: 1 | N36: 1 | AL36: =SUM(G36:AK36) -> 7 | AM36: 33000 | AN36: =AM36*AL36 -> 231000
A37: AC | B37: 304 | C37: AZOCAR | E37: NICOLAS | F37: 19114498-8 | H37: 1 | I37: 1 | J37: 1 | K37: 1 | L37: 1 | M37: 1 | N37: 1 | AL37: =SUM(G37:AK37) -> 7 | AM37: 33000 | AN37: =AM37*AL37 -> 231000
A38: AC | B38: 404 | C38: TENORIO | E38: JOSE | F38: 18579932-8 | H38: 1 | I38: 1 | J38: 1 | K38: 1 | L38: 1 | M38: 1 | N38: 1 | AL38: =SUM(G38:AK38) -> 7 | AM38: 33000 | AN38: =AM38*AL38 -> 231000
A39: AC | B39: 404 | C39: CARRASCO | E39: FELIPE | F39: 16690731-4 | H39: 1 | I39: 1 | J39: 1 | K39: 1 | L39: 1 | M39: 1 | N39: 1 | AL39: =SUM(G39:AK39) -> 7 | AM39: 33000 | AN39: =AM39*AL39 -> 231000
A40: AC | B40: 604 | C40: ALEGRIA | D40: HUERAMAN | E40: CARLOS | F40: 19835830-4 | H40: 1 | I40: 1 | J40: 1 | K40: 1 | L40: 1 | M40: 1 | N40: 1 | AL40: =SUM(G40:AK40) -> 7 | AM40: 33000 | AN40: =AM40*AL40 -> 231000
A41: AC | B41: 604 | C41: CUEVAS | D41: VALENZUELA | E41: SERGIO | F41: 19510126-4 | H41: 1 | I41: 1 | J41: 1 | K41: 1 | L41: 1 | M41: 1 | N41: 1 | AL41: =SUM(G41:AK41) -> 7 | AM41: 33000 | AN41: =AM41*AL41 -> 231000
A42: AC | B42: 903 | C42: CERECEDA | E42: SOLANGE | F42: 17172403-1 | H42: 1 | I42: 1 | J42: 1 | K42: 1 | L42: 1 | M42: 1 | N42: 1 | AL42: =SUM(G42:AK42) -> 7 | AM42: 33000 | AN42: =AM42*AL42 -> 231000
A43: AC | B43: 903 | C43: PEREZ | E43: MARIA | F43: 18785701-5 | H43: 1 | I43: 1 | J43: 1 | K43: 1 | L43: 1 | M43: 1 | N43: 1 | AL43: =SUM(G43:AK43) -> 7 | AM43: 33000 | AN43: =AM43*AL43 -> 231000
A44: AC | B44: 1101 | C44: BARRIENTOS | E44: ROCIO | F44: 19907354-0 | H44: 1 | I44: 1 | J44: 1 | K44: 1 | L44: 1 | M44: 1 | N44: 1 | AL44: =SUM(G44:AK44) -> 7 | AM44: 33000 | AN44: =AM44*AL44 -> 231000
A45: AC | B45: 1101 | C45: VALENZUELA | E45: VICTORIA | F45: 19120001-2 | H45: 1 | I45: 1 | J45: 1 | K45: 1 | L45: 1 | M45: 1 | N45: 1 | AL45: =SUM(G45:AK45) -> 7 | AM45: 33000 | AN45: =AM45*AL45 -> 231000
A46: AC | B46: 1302 | C46: FLORES | D46: BAUTISTA | E46: MILENA | F46: 18579932-8 | H46: 1 | I46: 1 | J46: 1 | K46: 1 | L46: 1 | M46: 1 | N46: 1 | AL46: =SUM(G46:AK46) -> 7 | AM46: 33000 | AN46: =AM46*AL46 -> 231000
A47: AC | B47: 1302 | C47: SOTO | D47: HERRERA | E47: MARIA | F47: 19797369-2 | H47: 1 | AL47: =SUM(G47:AK47) -> 1 | AM47: 33000 | AN47: =AM47*AL47 -> 33000
A48: AC | B48: 1402 | C48: CORNEJO | E48: RONALD | F48: 13507456-K | H48: 1 | I48: 1 | J48: 1 | K48: 1 | L48: 1 | M48: 1 | N48: 1 | AL48: =SUM(G48:AK48) -> 7 | AM48: 33000 | AN48: =AM48*AL48 -> 231000
A49: AC | B49: 1402 | C49: DUARTE | E49: JORGE | F49: 9635487-8 | H49: 1 | I49: 1 | J49: 1 | K49: 1 | L49: 1 | M49: 1 | N49: 1 | AL49: =SUM(G49:AK49) -> 7 | AM49: 33000 | AN49: =AM49*AL49 -> 231000
A50: AC | B50: 203 | C50: MOSCOSO | D50: SAEZ | E50: DANIEL | F50: 17678108-4 | O50: 1 | P50: 1 | AL50: =SUM(G50:AK50) -> 2 | AM50: 33000 | AN50: =AM50*AL50 -> 66000
A51: AC | B51: 203 | C51: SEPULVEDA | D51: ABURTO | E51: FERNANDO | F51: 17319810-8 | O51: 1 | P51: 1 | Q51: 1 | R51: 1 | AL51: =SUM(G51:AK51) -> 4 | AM51: 33000 | AN51: =AM51*AL51 -> 132000
A52: AC | B52: 205 | C52: VELIS | D52: VARAS | E52: CLAUDIO | F52: 16728609-7 | O52: 1 | P52: 1 | Q52: 1 | R52: 1 | S52: 1 | T52: 1 | U52: 1 | AL52: =SUM(G52:AK52) -> 7 | AM52: 33000 | AN52: =AM52*AL52 -> 231000
...

Sheet LT
A6: CORRELATIVO N°4 | G6: 45839 | H6: 45840 | I6: 45841 | J6: 45842 | K6: 45843 | L6: 45844 | M6: 45845 | N6: 45846 | O6: 45847 | P6: 45848 | Q6: 45849 | R6: 45850 | S6: 45851 | T6: 45852 | U6: 45853 | V6: 45854 | W6: 45855 | X6: 45856 | Y6: 45857 | Z6: 45858 | AA6: 45859 | AB6: 45860 | AC6: 45861 | AD6: 45862 | AE6: 45863 | AF6: 45864 | AG6: 45865 | AH6: 45866 | AI6: 45867 | AJ6: 45868 | AK6: 01 AL 31 DE JULIO
B9: HAB | C9: APELLIDO PATERNO | D9: APELLIDO MATERNO | E9: NOMBRE | F9: RUT | AK9: D. OCUP | AL9: V. OCUP | AM9: T. OCUP.
A10: LT | B10: 202 | C10: VARELA | D10: CONTRERAS | E10: HECTOR | F10: 13624141-9 | H10: 1 | I10: 1 | AK10: =SUM(G10:AJ10) -> 2 | AL10: 32000 | AM10: =AL10*AK10 -> 64000
A11: LT | B11: 202 | C11: SANCHEZ | D11: HANCCO | E11: WILSON | F11: 12493121-5 | H11: 1 | I11: 1 | AK11: =SUM(G11:AJ11) -> 2 | AL11: 32000 | AM11: =AL11*AK11 -> 64000
A12: LT | B12: 202 | C12: CCACALA | D12: YAMPASI | E12: JESUS | F12: 444849967 | H12: 1 | I12: 1 | AK12: =SUM(G12:AJ12) -> 2 | AL12: 32000 | AM12: =AL12*AK12 -> 64000
A13: LT | B13: 203 | C13: BERMEJO | D13: LEYTON | E13: JOSE | F13: 44471956-7 | H13: 1 | I13: 1 | AK13: =SUM(G13:AJ13) -> 2 | AL13: 32000 | AM13: =AL13*AK13 -> 64000
A14: LT | B14: 203 | C14: RAMOS | D14: JANAMPA | E14: RONY | F14: 44471941-9 | H14: 1 | I14: 1 | AK14: =SUM(G14:AJ14) -> 2 | AL14: 32000 | AM14: =AL14*AK14 -> 64000
A15: LT | B15: 203 | C15: UQUICHE | D15: FLORES | E15: LUIS | F15: 33133566-5 | H15: 1 | I15: 1 | AK15: =SUM(G15:AJ15) -> 2 | AL15: 32000 | AM15: =AL15*AK15 -> 64000
A16: LT | B16: 204 | C16: MONTALVO | D16: JIMENEZ | E16: ERICK | F16: 33573989-2 | H16: 1 | I16: 1 | AK16: =SUM(G16:AJ16) -> 2 | AL16: 32000 | AM16: =AL16*AK16 -> 64000
A17: LT | B17: 204 | C17: PANDURO | D17: DIAZ | E17: BILLY | F17: 44472384-K | H17: 1 | I17: 1 | AK17: =SUM(G17:AJ17) -> 2 | AL17: 32000 | AM17: =AL17*AK17 -> 64000
A18: LT | B18: 301 | C18: GUTIERREZ | D18: ZUÑIGA | E18: JOSE | F18: 19091189-6 | H18: 1 | I18: 1 | AK18: =SUM(G18:AJ18) -> 2 | AL18: 32000 | AM18: =AL18*AK18 -> 64000
A19: LT | B19: 303 | C19: CHURATA | D19: CHUQUIJA | E19: ELISEO | F19: 44472068-9 | H19: 1 | I19: 1 | AK19: =SUM(G19:AJ19) -> 2 | AL19: 32000 | AM19: =AL19*AK19 -> 64000
A20: LT | B20: 303 | C20: MATO | D20: FLORES | E20: ISAAC | F20: 44471932-K | H20: 1 | I20: 1 | AK20: =SUM(G20:AJ20) -> 2 | AL20: 32000 | AM20: =AL20*AK20 -> 64000
A21: LT | B21: 305 | C21: DIAZ | D21: CALLE | E21: ODAR | F21: 44472104-9 | H21: 1 | I21: 1 | AK21: =SUM(G21:AJ21) -> 2 | AL21: 32000 | AM21: =AL21*AK21 -> 64000
A22: LT | B22: 305 | C22: VILLAR | D22: FLORES | E22: EDGAR | F22: 33663428-8 | H22: 1 | I22: 1 | AK22: =SUM(G22:AJ22) -> 2 | AL22: 32000 | AM22: =AL22*AK22 -> 64000
A23: LT | B23: 306 | C23: SCHOTT | D23: HERRERA | E23: CRISTIAN | F23: 15452879-2 | H23: 1 | I23: 1 | AK23: =SUM(G23:AJ23) -> 2 | AL23: 32000 | AM23: =AL23*AK23 -> 64000
A24: LT | B24: 306 | C24: TORRES | D24: SEPULVEDA | E24: ISAIAS | F24: 12382889-5 | H24: 1 | I24: 1 | AK24: =SUM(G24:AJ24) -> 2 | AL24: 32000 | AM24: =AL24*AK24 -> 64000
... A31: LT | B31: 501 | C31: INZUNZA | D31: CHANDIA | E31: LUIS | F31: 13128159-5 | H31: 1 | I31: 1 | AK31: =SUM(G31:AJ31) -> 2 | AL31: 32000 | AM31: =AL31*AK31 -> 64000
G33: =SUM(G10:G32) -> 0 | H33: =SUM(H10:H32) -> 22 | I33: =SUM(I10:I32) -> 22 | J33: =SUM(J10:J32) -> 0 | K33: =SUM(K10:K32) -> 0 | L33: =SUM(L10:L32) -> 0 | M33: =SUM(M10:M32) -> 0 | N33: =SUM(N10:N32) -> 0 | ... AK33: =SUM(AK10:AK32) -> 44
AL35: TOTAL | AM35: =SUM(AM10:AM34) -> 1408000
A37: CORRELATIVO N°4 | G37: 45839 | H37: 45840 | I37: 45841 | J37: 45842 | K37: 45843 | L37: 45844 | M37: 45845 | N37: 45846 | O37: 45847 | P37: 45848 | Q37: 45849 | R37: 45850 | S37: 45851 | T37: 45852 | U37: 45853 | V37: 45854 | W37: 45855 | X37: 45856 | Y37: 45857 | Z37: 45858 | AA37: 45859 | AB37: 45860 | AC37: 45861 | AD37: 45862 | AE37: 45863 | AF37: 45864 | AG37: 45865 | AH37: 45866 | AI37: 45867 | AJ37: 45868 | AK37: 01 AL 31 DE JULIO
A40: ALMUERZOS | AK40: D. OCUP | AL40: V. OCUP | AM40: T. OCUP.
A41: 1 | B41: ALMUERZOS | H41: 13 | I41: 16 | AK41: =SUM(G41:AJ41) -> 29 | AL41: 8500 | AM41: =AL41*AK41 -> 246500
AL43: ALOJAMIENTO | AM43: =AM35 -> 1408000
AL44: ALMUERZOS | AM44: =AM41 -> 246500

Sheet H2
A6: CORRELATIVO N°4 | G6: 45868 | H6: 45869 | I6: 01 AL 31 DE JULIO
B9: HAB | C9: APELLIDO PATERNO | D9: APELLIDO MATERNO | E9: NOMBRE | F9: RUT | I9: D. OCUP | J9: V. OCUP | K9: T. OCUP.
A10: H2 | B10: 103 | C10: KERO | D10: HERNANDEZ | E10: PABLO | F10: 18788799-2 | G10: 1 | H10: 1 | I10: =SUM(G10:H10) -> 2 | J10: 32000 | K10: =J10*I10 -> 64000
A11: H2 | B11: 103 | C11: SANCHEZ | D11: CRISTALDO | E11: JORDAN | F11: 22038079-3 | G11: 1 | H11: 1 | I11: =SUM(G11:H11) -> 2 | J11: 32000 | K11: =J11*I11 -> 64000
A12: H2 | B12: 201 | C12: CALFUEQUE | D12: VERA | E12: DAGOBERTO | F12: 15554007-9 | G12: 1 | H12: 1 | I12: =SUM(G12:H12) -> 2 | J12: 32000 | K12: =J12*I12 -> 64000
A13: H2 | B13: 201 | C13: MATUS | D13: ESCOBAR | E13: RODOLFO | F13: 14059897-6 | G13: 1 | H13: 1 | I13: =SUM(G13:H13) -> 2 | J13: 32000 | K13: =J13*I13 -> 64000
A14: H2 | B14: 202 | C14: ALFARO | D14: ALFARO | E14: BENITO | F14: 16054392-2 | G14: 1 | H14: 1 | I14: =SUM(G14:H14) -> 2 | J14: 32000 | K14: =J14*I14 -> 64000
A15: H2 | B15: 202 | C15: TECHELET | E15: PIERRE | F15: 25980292-K | G15: 1 | H15: 1 | I15: =SUM(G15:H15) -> 2 | J15: 32000 | K15: =J15*I15 -> 64000
A16: H2 | B16: 203 | C16: ADAMAS | D16: REYES | E16: FERNANDO | F16: 16541548-5 | G16: 1 | H16: 1 | I16: =SUM(G16:H16) -> 2 | J16: 32000 | K16: =J16*I16 -> 64000
A17: H2 | B17: 203 | C17: ARAYA | D17: MARIN | E17: ISAAC | F17: 20167572-3 | G17: 1 | H17: 1 | I17: =SUM(G17:H17) -> 2 | J17: 32000 | K17: =J17*I17 -> 64000
A18: H2 | B18: 204 | C18: GONZALEZ | D18: ARRIGADA | E18: PATRICIA | F18: 12484559-9 | G18: 1 | H18: 1 | I18: =SUM(G18:H18) -> 2 | J18: 32000 | K18: =J18*I18 -> 64000
A19: H2 | B19: 205 | C19: ADAMAS | D19: REYES | E19: BRAYAN | F19: 17219265-3 | G19: 1 | H19: 1 | I19: =SUM(G19:H19) -> 2 | J19: 32000 | K19: =J19*I19 -> 64000
A20: H2 | B20: 205 | C20: ALVAREZ | D20: ADASMA | E20: IGNACIO | F20: 20924569-8 | G20: 1 | H20: 1 | I20: =SUM(G20:H20) -> 2 | J20: 32000 | K20: =J20*I20 -> 64000
A21: H2 | B21: 206 | C21: SEPULVEDA | D21: ALVIAL | E21: DANY | F21: 15180143-9 | G21: 1 | H21: 1 | I21: =SUM(G21:H21) -> 2 | J21: 32000 | K21: =J21*I21 -> 64000
A22: H2 | B22: 206 | C22: PRIETO | D22: MONTECINOS | E22: JOSE | F22: 19827281-7 | G22: 1 | H22: 1 | I22: =SUM(G22:H22) -> 2 | J22: 32000 | K22: =J22*I22 -> 64000
A23: H2 | B23: 301 | C23: MAURICIO | D23: VELASQUEZ | E23: HELBER | F23: 44484822-7 | G23: 1 | H23: 1 | I23: =SUM(G23:H23) -> 2 | J23: 32000 | K23: =J23*I23 -> 64000
A24: H2 | B24: 301 | C24: TUESTA | D24: DANTAS | E24: RAUL | F24: 33666443-8 | G24: 1 | H24: 1 | I24: =SUM(G24:H24) -> 2 | J24: 32000 | K24: =J24*I24 -> 64000
A25: H2 | B25: 302 | C25: CONSUEGRA | D25: ARCE | E25: WILLIAM | F25: 26341309-1 | G25: 1 | H25: 1 | I25: =SUM(G25:H25) -> 2 | J25: 32000 | K25: =J25*I25 -> 64000
A26: H2 | B26: 302 | C26: LIGNAI | D26: TRUJILLO | E26: LUIS | F26: 10516209-K | G26: 1 | H26: 1 | I26: =SUM(G26:H26) -> 2 | J26: 32000 | K26: =J26*I26 -> 64000
A27: H2 | B27: 303 | C27: YACTAYO | D27: VERGARAY | E27: JAIME | F27: 44484842-1 | G27: 1 | H27: 1 | I27: =SUM(G27:H27) -> 2 | J27: 32000 | K27: =J27*I27 -> 64000
... A35: H2 | B35: 401 | C35: HUAMACTO | D35: VIVANCO | E35: ALDO | F35: 33655503-5 | G35: 1 | H35: 1 | I35: =SUM(G35:H35) -> 2 | J35: 32000 | K35: =J35*I35 -> 64000
A36: H2 | B36: 401 | C36: SANCHEZ | D36: HANCCO | E36: WILSON | F36: 444849118 | G36: 1 | H36: 1 | I36: =SUM(G36:H36) -> 2 | J36: 32000 | K36: =J36*I36 -> 64000
A37: H2 | B37: 402 | C37: GONZALES | D37: PALOMINO | E37: LUIS | F37: 44484870-7 | G37: 1 | H37: 1 | I37: =SUM(G37:H37) -> 2 | J37: 32000 | K37: =J37*I37 -> 64000
A38: H2 | B38: 402 | C38: HUACCHA | D38: LLANOS | E38: PATRICIO | F38: 44486389-7 | G38: 1 | H38: 1 | I38: =SUM(G38:H38) -> 2 | J38: 32000 | K38: =J38*I38 -> 64000
A39: H2 | B39: 403 | C39: FUENTES | D39: CABRERA | E39: JAIME | F39: 14363777-8 | G39: 1 | H39: 1 | I39: =SUM(G39:H39) -> 2 | J39: 32000 | K39: =J39*I39 -> 64000
A40: H2 | B40: 403 | C40: CAAMAÑO | D40: CANCINO | E40: DIEGO | F40: 11790104-1 | G40: 1 | H40: 1 | I40: =SUM(G40:H40) -> 2 | J40: 32000 | K40: =J40*I40 -> 64000
A41: H2 | B41: 404 | C41: HUAMAN | D41: PAUCAR | E41: JUVELIO | F41: 33655736-4 | G41: 1 | H41: 1 | I41: =SUM(G41:H41) -> 2 | J41: 32000 | K41: =J41*I41 -> 64000
A42: H2 | B42: 404 | C42: CCACCALA | D42: YANPASI | E42: JESUS | F42: 444849967 | G42: 1 | H42: 1 | I42: =SUM(G42:H42) -> 2 | J42: 32000 | K42: =J42*I42 -> 64000
A43: H2 | B43: 405 | C43: RAVANAL | D43: BELMAR | E43: ALEJANDRO | F43: 19052453-1 | G43: 1 | H43: 1 | I43: =SUM(G43:H43) -> 2 | J43: 32000 | K43: =J43*I43 -> 64000
A44: H2 | B44: 405 | C44: TORRES | D44: BENITEZ | E44: ERIK | F44: 17870662-4 | G44: 1 | H44: 1 | I44: =SUM(G44:H44) -> 2 | J44: 32000 | K44: =J44*I44 -> 64000
A45: H2 | B45: 406 | C45: BRIONES | D45: LEAL | E45: MANUEL | F45: 13281520-8 | G45: 1 | H45: 1 | I45: =SUM(G45:H45) -> 2 | J45: 32000 | K45: =J45*I45 -> 64000
A46: H2 | B46: 406 | C46: CALPIQUEO | D46: PAILLACAN | E46: ALIRO | F46: 15239015-7 | G46: 1 | H46: 1 | I46: =SUM(G46:H46) -> 2 | J46: 32000 | K46: =J46*I46 -> 64000
A47: H2 | B47: 501 | C47: ACEVEDO | D47: LETELIER | E47: CRISTIAN | F47: 16856842-8 | G47: 1 | H47: 1 | I47: =SUM(G47:H47) -> 2 | J47: 32000 | K47: =J47*I47 -> 64000
A48: H2 | B48: 501 | C48: SOTO | D48: RODRIGUEZ | E48: ROBERTO | F48: 14332421-4 | G48: 1 | H48: 1 | I48: =SUM(G48:H48) -> 2 | J48: 32000 | K48: =J48*I48 -> 64000
A49: H2 | B49: 502 | C49: ROSALES | D49: ARAVENA | E49: LEANDRO | F49: 16140720-8 | G49: 1 | H49: 1 | I49: =SUM(G49:H49) -> 2 | J49: 32000 | K49: =J49*I49 -> 64000
A50: H2 | B50: 502 | C50: RUIZ | D50: MANRIQUEZ | E50: ERME | F50: 15209490-6 | G50: 1 | H50: 1 | I50: =SUM(G50:H50) -> 2 | J50: 32000 | K50: =J50*I50 -> 64000
A51: H2 | B51: 503 | C51: ANDIA | E51: RAUL | F51: 23105583-5 | G51: 1 | H51: 1 | I51: =SUM(G51:H51) -> 2 | J51: 32000 | K51: =J51*I51 -> 64000
A52: H2 | B52: 504 | C52: HUAYRA | D52: QUISPE | E52: FIDEL | F52: 44484808-1 | G52: 1 | H52: 1 | I52: =SUM(G52:H52) -> 2 | J52: 32000 | K52: =J52*I52 -> 64000
A53: H2 | B53: 504 | C53: ZAMBRANO | D53: QUISPE | E53: HERMINIO | F53: 44484835-9 | G53: 1 | H53: 1 | I53: =SUM(G53:H53) -> 2 | J53: 32000 | K53: =J53*I53 -> 64000
A54: H2 | B54: 505 | C54: ANCANAO | D54: RODRIGUEZ | E54: JUAN | F54: 15210383-2 | G54: 1 | H54: 1 | I54: =SUM(G54:H54) -> 2 | J54: 32000 | K54: =J54*I54 -> 64000
...
