Workbook

Sheet H1
A6: CORRELATIVO N°3 | G6: 45778 | H6: 45779 | I6: 45780 | J6: 45781 | K6: 45782 | L6: 45783 | M6: 45784 | N6: 45785 | O6: 45786 | P6: 45787 | Q6: 45788 | R6: 45789 | S6: 45790 | T6: 45791 | U6: 45792 | V6: 45793 | W6: 45794 | X6: 45795 | Y6: 45796 | Z6: 45797 | AA6: 45798 | AB6: 45799 | AC6: 45800 | AD6: 45801 | AE6: 45802 | AF6: 45803 | AG6: 45804 | AH6: 45805 | AI6: 45806 | AJ6: 45807 | AK6: 01 AL 30 DE JUNIO
B9: HAB | C9: APELLIDO PATERNO | D9: APELLIDO MATERNO | E9: NOMBRE | F9: RUT | AK9: D. OCUP | AL9: V. OCUP | AM9: T. OCUP.
A10: H1 | B10: 3 | C10: SOLIS | D10: HIDALGO | E10: ALEJANDRO | F10: 17078357-3 | G10: 1 | H10: 1 | I10: 1 | AK10: =SUM(G10:AJ10) -> 3 | AL10: 32000 | AM10: =AL10*AK10 -> 96000
A11: H1 | B11: 3 | C11: SANTANDER | D11: ÁVILES | E11: JAVIER | F11: 15183270-9 | G11: 1 | H11: 1 | I11: 1 | AK11: =SUM(G11:AJ11) -> 3 | AL11: 32000 | AM11: =AL11*AK11 -> 96000
A12: H1 | B12: 5 | C12: ORTIZ | D12: ORTIZ | E12: JUAN | F12: 15198618-8 | G12: 1 | H12: 1 | I12: 1 | AK12: =SUM(G12:AJ12) -> 3 | AL12: 32000 | AM12: =AL12*AK12 -> 96000
A13: H1 | B13: 5 | C13: ROMERO | D13: PACHECO | E13: CRISTIAN | F13: 11963508-K | G13: 1 | H13: 1 | I13: 1 | AK13: =SUM(G13:AJ13) -> 3 | AL13: 32000 | AM13: =AL13*AK13 -> 96000
A14: H1 | B14: 9 | C14: MUÑOZ | D14: QUEZADA | E14: MIGUEL | F14: 15819396-5 | G14: 1 | H14: 1 | I14: 1 | AK14: =SUM(G14:AJ14) -> 3 | AL14: 32000 | AM14: =AL14*AK14 -> 96000
A15: H1 | B15: 10 | C15: PINCHON | D15: CORNEJO | E15: MARCO | F15: 12915179-K | G15: 1 | H15: 1 | I15: 1 | AK15: =SUM(G15:AJ15) -> 3 | AL15: 32000 | AM15: =AL15*AK15 -> 96000
A16: H1 | B16: 10 | C16: INOSTROZA | D16: INOSTROZA | E16: RINDOLFO | F16: 11585182-9 | G16: 1 | H16: 1 | I16: 1 | AK16: =SUM(G16:AJ16) -> 3 | AL16: 32000 | AM16: =AL16*AK16 -> 96000
A17: H1 | B17: 11 | C17: VILLAGRA | D17: AEDO | E17: IGNACIO | F17: 19090851-8 | G17: 1 | H17: 1 | I17: 1 | AK17: =SUM(G17:AJ17) -> 3 | AL17: 32000 | AM17: =AL17*AK17 -> 96000
A18: H1 | B18: 11 | C18: ESPINOZA | D18: ESPINOZA | E18: RODOLFO | F18: 16090751-7 | G18: 1 | H18: 1 | I18: 1 | AK18: =SUM(G18:AJ18) -> 3 | AL18: 32000 | AM18: =AL18*AK18 -> 96000
A19: H1 | B19: 13 | C19: ALMAZABAL | D19: SAAVEDRA | E19: OMERANDO | F19: 14444202-4 | G19: 1 | H19: 1 | I19: 1 | AK19: =SUM(G19:AJ19) -> 3 | AL19: 32000 | AM19: =AL19*AK19 -> 96000
A20: H1 | B20: 13 | C20: VERGARA | D20: CONTRERAS | E20: CLAUDIO | F20: 12521035-K | G20: 1 | H20: 1 | I20: 1 | AK20: =SUM(G20:AJ20) -> 3 | AL20: 32000 | AM20: =AL20*AK20 -> 96000
A21: H1 | B21: 15 | C21: IBACETA | D21: PORMA | E21: FRANCHESCA | F21: 20408882-9 | G21: 1 | H21: 1 | I21: 1 | AK21: =SUM(G21:AJ21) -> 3 | AL21: 32000 | AM21: =AL21*AK21 -> 96000
... A24: H1 | B24: 18 | C24: ORTEGA | D24: CERDA | E24: RAUL | F24: 19410879-6 | G24: 1 | H24: 1 | I24: 1 | AK24: =SUM(G24:AJ24) -> 3 | AL24: 32000 | AM24: =AL24*AK24 -> 96000
A25: H1 | B25: 20 | C25: ÑANCO | D25: MILLALEN | E25: LUIS | F25: 15248769-K | G25: 1 | H25: 1 | AK25: =SUM(G25:AJ25) -> 2 | AL25: 32000 | AM25: =AL25*AK25 -> 64000
A26: H1 | B26: 22 | C26: CASTRO | D26: LEON | E26: CLAUDIO | F26: 19045218-2 | G26: 1 | H26: 1 | AK26: =SUM(G26:AJ26) -> 2 | AL26: 32000 | AM26: =AL26*AK26 -> 64000
A27: H1 | B27: 22 | C27: RIFFO | D27: CISTERNAS | E27: SERGIO | F27: 15728475-4 | G27: 1 | H27: 1 | AK27: =SUM(G27:AJ27) -> 2 | AL27: 32000 | AM27: =AL27*AK27 -> 64000
A28: H1 | B28: 24 | C28: PEZO | D28: MONTENEGRO | E28: MAURICIO | F28: 15568743-6 | G28: 1 | H28: 1 | AK28: =SUM(G28:AJ28) -> 2 | AL28: 32000 | AM28: =AL28*AK28 -> 64000
A29: H1 | B29: 24 | C29: CARO | D29: CONTRERAS | E29: JOSÉ | F29: 12051577-2 | G29: 1 | H29: 1 | AK29: =SUM(G29:AJ29) -> 2 | AL29: 32000 | AM29: =AL29*AK29 -> 64000
A30: H1 | B30: 26 | C30: ARANCIBIA | D30: OVALLE | E30: ROBERTO | F30: 9347291-8 | G30: 1 | H30: 1 | AK30: =SUM(G30:AJ30) -> 2 | AL30: 32000 | AM30: =AL30*AK30 -> 64000
A31: H1 | B31: 26 | C31: SAAVEDRA | D31: FUENSALIDA | E31: ESTEBAN | F31: 15753932-9 | G31: 1 | H31: 1 | AK31: =SUM(G31:AJ31) -> 2 | AL31: 32000 | AM31: =AL31*AK31 -> 64000
A32: H1 | B32: 27 | C32: CONTRERAS | D32: CONTRERAS | E32: JAVIER | F32: 19320445-7 | G32: 1 | H32: 1 | AK32: =SUM(G32:AJ32) -> 2 | AL32: 32000 | AM32: =AL32*AK32 -> 64000
A33: H1 | B33: 27 | C33: CONTRERAS | D33: SEPULVEDA | E33: CRISTIAN | F33: 14389879-2 | G33: 1 | H33: 1 | AK33: =SUM(G33:AJ33) -> 2 | AL33: 32000 | AM33: =AL33*AK33 -> 64000
A34: H1 | B34: 28 | C34: CARMONA | D34: CASTILLO | E34: BENJAMIN | F34: 20152621-3 | G34: 1 | H34: 1 | I34: 1 | AK34: =SUM(G34:AJ34) -> 3 | AL34: 32000 | AM34: =AL34*AK34 -> 96000
A35: H1 | B35: 28 | C35: VENEGAS | D35: GARCES | E35: HERNAN | F35: 16641048-7 | G35: 1 | H35: 1 | I35: 1 | AK35: =SUM(G35:AJ35) -> 3 | AL35: 32000 | AM35: =AL35*AK35 -> 96000
A36: H1 | B36: 29 | C36: COMICHEO | D36: VIDAL | E36: ISAAC | F36: 20550837-6 | G36: 1 | H36: 1 | I36: 1 | AK36: =SUM(G36:AJ36) -> 3 | AL36: 32000 | AM36: =AL36*AK36 -> 96000
A37: H1 | B37: 29 | C37: SOLAR | D37: PARRA | E37: MARCELO | F37: 18318800-3 | G37: 1 | H37: 1 | I37: 1 | AK37: =SUM(G37:AJ37) -> 3 | AL37: 32000 | AM37: =AL37*AK37 -> 96000
A38: H1 | B38: 30 | C38: CONSTANZO | D38: JELVEZ | E38: ROBERTO | F38: 14028085-2 | G38: 1 | H38: 1 | I38: 1 | AK38: =SUM(G38:AJ38) -> 3 | AL38: 32000 | AM38: =AL38*AK38 -> 96000
A39: H1 | B39: 30 | C39: MONJE | D39: GARAY | E39: CRISTIAN | F39: 15962839-6 | G39: 1 | H39: 1 | I39: 1 | AK39: =SUM(G39:AJ39) -> 3 | AL39: 32000 | AM39: =AL39*AK39 -> 96000
A40: H1 | B40: 33 | C40: CID | D40: URRIOLA | E40: IVAN MAURICIO | F40: 12463574-8 | G40: 1 | H40: 1 | I40: 1 | AK40: =SUM(G40:AJ40) -> 3 | AL40: 32000 | AM40: =AL40*AK40 -> 96000
A41: H1 | B41: 33 | C41: TOLEDO | D41: JARA | E41: JOSE ABELARDO | F41: 9092883-K | G41: 1 | H41: 1 | I41: 1 | AK41: =SUM(G41:AJ41) -> 3 | AL41: 32000 | AM41: =AL41*AK41 -> 96000
A42: H1 | B42: 35 | C42: LEPE | D42: HERRERA | E42: FRANCISCO | F42: 11582166-0 | G42: 1 | H42: 1 | I42: 1 | AK42: =SUM(G42:AJ42) -> 3 | AL42: 32000 | AM42: =AL42*AK42 -> 96000
A43: H1 | B43: 35 | C43: MELLADO | D43: RIVERA | E43: BASTIAN | F43: 20907528-8 | G43: 1 | H43: 1 | I43: 1 | AK43: =SUM(G43:AJ43) -> 3 | AL43: 32000 | AM43: =AL43*AK43 -> 96000
A44: H1 | B44: 37 | C44: ANTINAO | D44: CALFIQUEO | E44: JUAN | F44: 17446134-1 | G44: 1 | H44: 1 | I44: 1 | AK44: =SUM(G44:AJ44) -> 3 | AL44: 32000 | AM44: =AL44*AK44 -> 96000
A45: H1 | B45: 37 | C45: DOMINGUEZ | D45: FIGUEROA | E45: FERNANDO | F45: 10822787-7 | G45: 1 | H45: 1 | I45: 1 | AK45: =SUM(G45:AJ45) -> 3 | AL45: 32000 | AM45: =AL45*AK45 -> 96000
... A140: H1 | B140: 109 | C140: CESPEDES | D140: GALLARDO | E140: ANGELO | F140: 15592455-4 | G140: 1 | H140: 1 | I140: 1 | AK140: =SUM(G140:AJ140) -> 3 | AL140: 32000 | AM140: =AL140*AK140 -> 96000
A141: H1 | B141: 110 | C141: SILVA | E141: PABLO | F141: 12973296-5 | G141: 1 | H141: 1 | I141: 1 | AK141: =SUM(G141:AJ141) -> 3 | AL141: 32000 | AM141: =AL141*AK141 -> 96000
A142: H1 | B142: 110 | C142: CIFUENTES | D142: ALARCON | E142: JOSE | F142: 15190004-6 | G142: 1 | H142: 1 | I142: 1 | AK142: =SUM(G142:AJ142) -> 3 | AL142: 32000 | AM142: =AL142*AK142 -> 96000
A143: H1 | B143: 111 | C143: FUENZALIDA | D143: SCHIPMAN | E143: CRISTIAN | F143: 19038296-6 | G143: 1 | H143: 1 | I143: 1 | AK143: =SUM(G143:AJ143) -> 3 | AL143: 32000 | AM143: =AL143*AK143 -> 96000
...

Sheet H3
A6: CORRELATIVO N°2 | G6: 45809 | H6: 45810 | I6: 45811 | J6: 45812 | K6: 45813 | L6: 45814 | M6: 45815 | N6: 45816 | O6: 45817 | P6: 45818 | Q6: 45819 | R6: 45820 | S6: 45821 | T6: 45822 | U6: 45823 | V6: 45824 | W6: 45825 | X6: 45826 | Y6: 45827 | Z6: 45828 | AA6: 45829 | AB6: 45830 | AC6: 45831 | AD6: 45832 | AE6: 45833 | AF6: 45834 | AG6: 45835 | AH6: 45836 | AI6: 45837 | AJ6: 45838 | AK6: 01 AL 30 DE JUNIO
B9: HAB | C9: APELLIDO PATERNO | D9: APELLIDO MATERNO | E9: NOMBRE | F9: RUT | AK9: D. OCUP | AL9: V. OCUP | AM9: T. OCUP.
A10: H3 | B10: 2 | C10: NUÑEZ | D10: CANCINO | E10: LUIS | F10: 15222340-4 | G10: 1 | H10: 1 | I10: 1 | AK10: =SUM(G10:AJ10) -> 3 | AL10: 32000 | AM10: =AL10*AK10 -> 96000
A11: H3 | B11: 29 | C11: MOLINA | D11: JARPA | E11: GERARDO | F11: 14210107-6 | G11: 1 | H11: 1 | I11: 1 | AK11: =SUM(G11:AJ11) -> 3 | AL11: 32000 | AM11: =AL11*AK11 -> 96000
A12: H3 | B12: 29 | C12: LANDERO | D12: LANDERO | E12: JUAN | F12: 11241778-8 | G12: 1 | H12: 1 | I12: 1 | AK12: =SUM(G12:AJ12) -> 3 | AL12: 32000 | AM12: =AL12*AK12 -> 96000
A13: H3 | B13: 46 | C13: VILLAGRA | D13: GONZALEZ | E13: CHRISTOPHER | F13: 19376474-6 | G13: 1 | H13: 1 | I13: 1 | AK13: =SUM(G13:AJ13) -> 3 | AL13: 32000 | AM13: =AL13*AK13 -> 96000
A14: H3 | B14: 46 | C14: ORTIZ | D14: ORTIZ | E14: FRANCO | F14: 16504476-2 | G14: 1 | H14: 1 | I14: 1 | AK14: =SUM(G14:AJ14) -> 3 | AL14: 32000 | AM14: =AL14*AK14 -> 96000
A15: H3 | B15: 48 | C15: RODRÍGUEZ | D15: MUÑOZ | E15: JOSE | F15: 19908182-9 | G15: 1 | H15: 1 | I15: 1 | AK15: =SUM(G15:AJ15) -> 3 | AL15: 32000 | AM15: =AL15*AK15 -> 96000
A16: H3 | B16: 48 | C16: CANALES | D16: LAGOS | E16: MATIAS | F16: 21830481-8 | G16: 1 | H16: 1 | I16: 1 | AK16: =SUM(G16:AJ16) -> 3 | AL16: 32000 | AM16: =AL16*AK16 -> 96000
A17: H3 | B17: 49 | C17: CONTRERAS | D17: POLANCO | E17: JORGE | F17: 17287619-6 | G17: 1 | H17: 1 | I17: 1 | AK17: =SUM(G17:AJ17) -> 3 | AL17: 32000 | AM17: =AL17*AK17 -> 96000
A18: H3 | B18: 51 | C18: LAGOS | D18: SILVA | E18: FABIAN | F18: 13151852-8 | G18: 1 | H18: 1 | I18: 1 | AK18: =SUM(G18:AJ18) -> 3 | AL18: 32000 | AM18: =AL18*AK18 -> 96000
A19: H3 | B19: 51 | C19: DIAZ | D19: GALLEGOS | E19: MANUEL | F19: 15247087-8 | G19: 1 | H19: 1 | I19: 1 | AK19: =SUM(G19:AJ19) -> 3 | AL19: 32000 | AM19: =AL19*AK19 -> 96000
A20: H3 | B20: 53 | C20: HERNANDEZ | D20: ZAVALA | E20: MICHAEL | F20: 20891578-9 | G20: 1 | H20: 1 | I20: 1 | AK20: =SUM(G20:AJ20) -> 3 | AL20: 32000 | AM20: =AL20*AK20 -> 96000
A21: H3 | B21: 53 | C21: CID | D21: RODRIGUEZ | E21: DAVID | F21: 13957122-3 | G21: 1 | H21: 1 | I21: 1 | AK21: =SUM(G21:AJ21) -> 3 | AL21: 32000 | AM21: =AL21*AK21 -> 96000
A22: H3 | B22: 61 | C22: PARRA | D22: ESPINOZA | E22: MOISES | F22: 11901984-2 | G22: 1 | H22: 1 | I22: 1 | AK22: =SUM(G22:AJ22) -> 3 | AL22: 32000 | AM22: =AL22*AK22 -> 96000
A23: H3 | B23: 1 | C23: ESCOBAR | D23: ARRIAGAA | E23: PATRICIO | F23: 18405090-0 | J23: 1 | K23: 1 | L23: 1 | M23: 1 | N23: 1 | O23: 1 | P23: 1 | Q23: 1 | R23: 1 | S23: 1 | T23: 1 | U23: 1 | V23: 1 | W23: 1 | AK23: =SUM(G23:AJ23) -> 14 | AL23: 32000 | AM23: =AL23*AK23 -> 448000
A24: H3 | B24: 1 | C24: FIGUEROA | D24: MUÑOZ | E24: SERGIO | F24: 11215037-4 | J24: 1 | K24: 1 | L24: 1 | M24: 1 | N24: 1 | O24: 1 | P24: 1 | Q24: 1 | R24: 1 | S24: 1 | T24: 1 | U24: 1 | V24: 1 | W24: 1 | AK24: =SUM(G24:AJ24) -> 14 | AL24: 32000 | AM24: =AL24*AK24 -> 448000
A25: H3 | B25: 2 | C25: NUÑEZ | D25: CANCINO | E25: LUIS | F25: 15222340-4 | J25: 1 | K25: 1 | L25: 1 | M25: 1 | N25: 1 | O25: 1 | P25: 1 | Q25: 1 | R25: 1 | S25: 1 | T25: 1 | U25: 1 | V25: 1 | W25: 1 | AK25: =SUM(G25:AJ25) -> 14 | AL25: 32000 | AM25: =AL25*AK25 -> 448000
A26: H3 | B26: 2 | C26: PARRA | D26: ESPINOZA | E26: MOISES | F26: 11901984-2 | J26: 1 | K26: 1 | L26: 1 | M26: 1 | N26: 1 | O26: 1 | P26: 1 | Q26: 1 | R26: 1 | S26: 1 | T26: 1 | U26: 1 | V26: 1 | W26: 1 | AK26: =SUM(G26:AJ26) -> 14 | AL26: 32000 | AM26: =AL26*AK26 -> 448000
A27: H3 | B27: 16 | C27: CARTES | D27: ARRIAGADA | E27: MARCELO | F27: 19767976-K | J27: 1 | K27: 1 | L27: 1 | M27: 1 | N27: 1 | O27: 1 | P27: 1 | Q27: 1 | R27: 1 | S27: 1 | T27: 1 | U27: 1 | V27: 1 | W27: 1 | AK27: =SUM(G27:AJ27) -> 14 | AL27: 32000 | AM27: =AL27*AK27 -> 448000
A28: H3 | B28: 16 | C28: JARA | D28: ZAPATA | E28: JUAN | F28: 14573834-7 | J28: 1 | K28: 1 | L28: 1 | M28: 1 | N28: 1 | O28: 1 | P28: 1 | Q28: 1 | R28: 1 | S28: 1 | T28: 1 | U28: 1 | V28: 1 | W28: 1 | AK28: =SUM(G28:AJ28) -> 14 | AL28: 32000 | AM28: =AL28*AK28 -> 448000
A29: H3 | B29: 20 | C29: TORRES | D29: BENITEZ | E29: ERIK | F29: 17870662-4 | J29: 1 | K29: 1 | L29: 1 | M29: 1 | N29: 1 | O29: 1 | P29: 1 | Q29: 1 | R29: 1 | S29: 1 | T29: 1 | U29: 1 | V29: 1 | W29: 1 | AK29: =SUM(G29:AJ29) -> 14 | AL29: 32000 | AM29: =AL29*AK29 -> 448000
A30: H3 | B30: 20 | C30: ARENAS | D30: MANRIQUEZ | E30: DANIEL | F30: 11179233-K | J30: 1 | K30: 1 | L30: 1 | M30: 1 | N30: 1 | O30: 1 | P30: 1 | Q30: 1 | R30: 1 | S30: 1 | T30: 1 | U30: 1 | V30: 1 | W30: 1 | AK30: =SUM(G30:AJ30) -> 14 | AL30: 32000 | AM30: =AL30*AK30 -> 448000
A31: H3 | B31: 29 | C31: MOLINA | D31: JARPA | E31: GERARDO | F31: 14210107-6 | J31: 1 | K31: 1 | L31: 1 | M31: 1 | N31: 1 | O31: 1 | P31: 1 | Q31: 1 | R31: 1 | S31: 1 | T31: 1 | U31: 1 | V31: 1 | W31: 1 | AK31: =SUM(G31:AJ31) -> 14 | AL31: 32000 | AM31: =AL31*AK31 -> 448000
A32: H3 | B32: 29 | C32: LANDERO | D32: LANDERO | E32: JUAN | F32: 11241778-8 | J32: 1 | K32: 1 | L32: 1 | M32: 1 | N32: 1 | O32: 1 | P32: 1 | Q32: 1 | R32: 1 | S32: 1 | T32: 1 | U32: 1 | V32: 1 | W32: 1 | AK32: =SUM(G32:AJ32) -> 14 | AL32: 32000 | AM32: =AL32*AK32 -> 448000
A33: H3 | B33: 30 | C33: COFRE | D33: TRONCOSO | E33: PATRICIO | F33: 13155394-3 | J33: 1 | K33: 1 | L33: 1 | M33: 1 | N33: 1 | O33: 1 | P33: 1 | Q33: 1 | R33: 1 | S33: 1 | T33: 1 | U33: 1 | V33: 1 | W33: 1 | AK33: =SUM(G33:AJ33) -> 14 | AL33: 32000 | AM33: =AL33*AK33 -> 448000
A34: H3 | B34: 30 | C34: ANCANAO | D34: RODRIGUEZ | E34: JUAN | F34: 15210383-2 | J34: 1 | K34: 1 | L34: 1 | M34: 1 | N34: 1 | O34: 1 | P34: 1 | Q34: 1 | R34: 1 | S34: 1 | T34: 1 | U34: 1 | V34: 1 | W34: 1 | AK34: =SUM(G34:AJ34) -> 14 | AL34: 32000 | AM34: =AL34*AK34 -> 448000
... A42: H3 | B42: 51 | C42: DÍAZ | D42: GALLEGOS | E42: MANUEL | F42: 15247087-8 | J42: 1 | K42: 1 | L42: 1 | M42: 1 | N42: 1 | O42: 1 | P42: 1 | Q42: 1 | R42: 1 | S42: 1 | T42: 1 | U42: 1 | V42: 1 | W42: 1 | AK42: =SUM(G42:AJ42) -> 14 | AL42: 32000 | AM42: =AL42*AK42 -> 448000
A43: H3 | B43: 53 | C43: TECHELET | E43: PIERRE | F43: 25980292-K | J43: 1 | K43: 1 | L43: 1 | M43: 1 | N43: 1 | O43: 1 | P43: 1 | Q43: 1 | R43: 1 | S43: 1 | T43: 1 | U43: 1 | V43: 1 | W43: 1 | AK43: =SUM(G43:AJ43) -> 14 | AL43: 32000 | AM43: =AL43*AK43 -> 448000
A44: H3 | B44: 53 | C44: ALFARO | D44: ALFARO | E44: BENITO | F44: 16054392-2 | J44: 1 | K44: 1 | L44: 1 | M44: 1 | N44: 1 | O44: 1 | P44: 1 | Q44: 1 | R44: 1 | S44: 1 | T44: 1 | U44: 1 | V44: 1 | W44: 1 | AK44: =SUM(G44:AJ44) -> 14 | AL44: 32000 | AM44: =AL44*AK44 -> 448000
A45: H3 | B45: 73 | C45: FUENTES | D45: CABRERA | E45: JAIME | F45: 14303777-8 | J45: 1 | K45: 1 | L45: 1 | M45: 1 | N45: 1 | O45: 1 | P45: 1 | Q45: 1 | R45: 1 | S45: 1 | T45: 1 | U45: 1 | V45: 1 | W45: 1 | AK45: =SUM(G45:AJ45) -> 14 | AL45: 32000 | AM45: =AL45*AK45 -> 448000
A46: H3 | B46: 77 | C46: MERA | D46: VICENCIO | E46: CARLOS | F46: 22285961-1 | J46: 1 | K46: 1 | L46: 1 | M46: 1 | N46: 1 | O46: 1 | P46: 1 | Q46: 1 | R46: 1 | S46: 1 | T46: 1 | U46: 1 | V46: 1 | W46: 1 | AK46: =SUM(G46:AJ46) -> 14 | AL46: 32000 | AM46: =AL46*AK46 -> 448000
A47: H3 | B47: 77 | C47: VILLAR | D47: ARANDA | E47: MICHAEL | F47: 17905126-5 | J47: 1 | K47: 1 | L47: 1 | M47: 1 | N47: 1 | O47: 1 | P47: 1 | Q47: 1 | R47: 1 | S47: 1 | T47: 1 | U47: 1 | V47: 1 | W47: 1 | AK47: =SUM(G47:AJ47) -> 14 | AL47: 32000 | AM47: =AL47*AK47 -> 448000
A48: H3 | B48: 75 | C48: CORNEJO | D48: OCHOA | E48: RONALD | F48: 13507456-K | W48: 1 | AK48: =SUM(G48:AJ48) -> 1 | AL48: 32000 | AM48: =AL48*AK48 -> 32000 | AN48: 8x6
A49: H3 | B49: 75 | C49: DUARTE | D49: GOMEZ | E49: JORGE | F49: 9635487-8 | W49: 1 | AK49: =SUM(G49:AJ49) -> 1 | AL49: 32000 | AM49: =AL49*AK49 -> 32000 | AN49: 8x6
A50: H3 | B50: 76 | C50: BARRIENTOS | D50: URQUIZA | E50: ROCIO | F50: 19907354-0 | W50: 1 | AK50: =SUM(G50:AJ50) -> 1 | AL50: 32000 | AM50: =AL50*AK50 -> 32000 | AN50: 8x6
A51: H3 | B51: 76 | C51: VALENZUELA | D51: BUSTOS | E51: VICTORIA | F51: 19120001-2 | W51: 1 | AK51: =SUM(G51:AJ51) -> 1 | AL51: 32000 | AM51: =AL51*AK51 -> 32000 | AN51: 8x6
A52: H3 | B52: 79 | C52: PEREZ | E52: MARIA F | F52: 18785701-5 | W52: 1 | AK52: =SUM(G52:AJ52) -> 1 | AL52: 32000 | AM52: =AL52*AK52 -> 32000 | AN52: 8x6
A53: H3 | B53: 82 | C53: AGUILERA | E53: JORGE | F53: 19797369-2 | W53: 1 | AK53: =SUM(G53:AJ53) -> 1 | AL53: 32000 | AM53: =AL53*AK53 -> 32000 | AN53: 8x6
A54: H3 | B54: 82 | C54: AZOCAR | D54: CORNEJO | E54: NICOLAS | F54: 19114498-8 | W54: 1 | AK54: =SUM(G54:AJ54) -> 1 | AL54: 32000 | AM54: =AL54*AK54 -> 32000 | AN54: 8x6
...

Sheet H7
A6: CORRELATIVO N°2 | G6: 45809 | H6: 45810 | I6: 45811 | J6: 45812 | K6: 45813 | L6: 45814 | M6: 45815 | N6: 45816 | O6: 45817 | P6: 45818 | Q6: 45819 | R6: 45820 | S6: 45821 | T6: 45822 | U6: 45823 | V6: 45824 | W6: 45825 | X6: 45826 | Y6: 45827 | Z6: 45828 | AA6: 45829 | AB6: 45830 | AC6: 45831 | AD6: 45832 | AE6: 45833 | AF6: 45834 | AG6: 45835 | AH6: 45836 | AI6: 45837 | AJ6: 45838 | AK6: 01 AL 30 DE JUNIO
B9: HAB | C9: APELLIDO PATERNO | D9: APELLIDO MATERNO | E9: NOMBRE | F9: RUT | AK9: D. OCUP | AL9: V. OCUP | AM9: T. OCUP.
A10: H7 | B10: 4 | C10: HUACCHA | D10: LLANOS | E10: PATRICIO | F10: 9739792 | K10: 1 | L10: 1 | M10: 1 | N10: 1 | O10: 1 | P10: 1 | Q10: 1 | R10: 1 | S10: 1 | T10: 1 | U10: 1 | V10: 1 | W10: 1 | AK10: =SUM(G10:AJ10) -> 13 | AL10: 32000 | AM10: =AL10*AK10 -> 416000
A11: H7 | B11: 4 | C11: ZAMBRANO | D11: QUISPE | E11: HERMINIO | F11: 45359428 | K11: 1 | L11: 1 | M11: 1 | N11: 1 | O11: 1 | P11: 1 | Q11: 1 | R11: 1 | S11: 1 | T11: 1 | U11: 1 | V11: 1 | W11: 1 | AK11: =SUM(G11:AJ11) -> 13 | AL11: 32000 | AM11: =AL11*AK11 -> 416000
A12: H7 | B12: 9 | C12: RAMOS | D12: JANAMPA | E12: RONY | F12: 44246612 | K12: 1 | L12: 1 | M12: 1 | N12: 1 | O12: 1 | P12: 1 | Q12: 1 | R12: 1 | S12: 1 | T12: 1 | U12: 1 | V12: 1 | W12: 1 | X12: 1 | AK12: =SUM(G12:AJ12) -> 14 | AL12: 32000 | AM12: =AL12*AK12 -> 448000
A13: H7 | B13: 9 | C13: RODRIGUEZ | D13: VARAS | E13: REYNER | F13: 46185887 | K13: 1 | L13: 1 | M13: 1 | N13: 1 | O13: 1 | P13: 1 | Q13: 1 | R13: 1 | S13: 1 | T13: 1 | U13: 1 | V13: 1 | W13: 1 | X13: 1 | AK13: =SUM(G13:AJ13) -> 14 | AL13: 32000 | AM13: =AL13*AK13 -> 448000
A14: H7 | B14: 11 | C14: DE LA CRUZ | D14: PAYTAN | E14: VICTOR | F14: 23269394 | K14: 1 | L14: 1 | M14: 1 | N14: 1 | O14: 1 | P14: 1 | Q14: 1 | R14: 1 | S14: 1 | T14: 1 | U14: 1 | V14: 1 | W14: 1 | X14: 1 | AK14: =SUM(G14:AJ14) -> 14 | AL14: 32000 | AM14: =AL14*AK14 -> 448000
A15: H7 | B15: 11 | C15: VARGAS | D15: PADILLA | E15: FELIX | F15: 31934043 | K15: 1 | L15: 1 | M15: 1 | N15: 1 | O15: 1 | P15: 1 | Q15: 1 | R15: 1 | S15: 1 | T15: 1 | U15: 1 | V15: 1 | W15: 1 | X15: 1 | AK15: =SUM(G15:AJ15) -> 14 | AL15: 32000 | AM15: =AL15*AK15 -> 448000
A16: H7 | B16: 13 | C16: HUAYRA | D16: QUISPE | E16: FIDEL | F16: 40707275 | K16: 1 | L16: 1 | M16: 1 | N16: 1 | O16: 1 | P16: 1 | Q16: 1 | R16: 1 | S16: 1 | T16: 1 | U16: 1 | V16: 1 | W16: 1 | AK16: =SUM(G16:AJ16) -> 13 | AL16: 32000 | AM16: =AL16*AK16 -> 416000
A17: H7 | B17: 13 | C17: SANCHEZ | D17: SATALAYA | E17: GENIX | F17: 46081253 | K17: 1 | L17: 1 | M17: 1 | N17: 1 | O17: 1 | P17: 1 | Q17: 1 | R17: 1 | S17: 1 | T17: 1 | U17: 1 | V17: 1 | W17: 1 | AK17: =SUM(G17:AJ17) -> 13 | AL17: 32000 | AM17: =AL17*AK17 -> 416000
A18: H7 | B18: 14 | C18: BERMEJO | D18: LEYTON | E18: JOSE | F18: 40769939 | K18: 1 | L18: 1 | M18: 1 | N18: 1 | O18: 1 | P18: 1 | Q18: 1 | R18: 1 | S18: 1 | T18: 1 | U18: 1 | V18: 1 | W18: 1 | X18: 1 | AK18: =SUM(G18:AJ18) -> 14 | AL18: 32000 | AM18: =AL18*AK18 -> 448000
A19: H7 | B19: 15 | C19: YACTAYO | D19: VERGARAY | E19: JAIME | F19: 80088096 | K19: 1 | L19: 1 | M19: 1 | N19: 1 | O19: 1 | P19: 1 | Q19: 1 | R19: 1 | S19: 1 | T19: 1 | U19: 1 | V19: 1 | W19: 1 | AK19: =SUM(G19:AJ19) -> 13 | AL19: 32000 | AM19: =AL19*AK19 -> 416000
A20: H7 | B20: 15 | C20: INOSTROZA | D20: ARAUJO | E20: JOSE | F20: 444719257 | K20: 1 | L20: 1 | M20: 1 | N20: 1 | O20: 1 | P20: 1 | Q20: 1 | R20: 1 | S20: 1 | T20: 1 | U20: 1 | V20: 1 | W20: 1 | AK20: =SUM(G20:AJ20) -> 13 | AL20: 32000 | AM20: =AL20*AK20 -> 416000
A21: H7 | B21: 16 | C21: MAMANI | D21: AREVALO | E21: JESUS | F21: 44181783 | K21: 1 | L21: 1 | M21: 1 | N21: 1 | O21: 1 | P21: 1 | Q21: 1 | R21: 1 | S21: 1 | T21: 1 | U21: 1 | V21: 1 | W21: 1 | AK21: =SUM(G21:AJ21) -> 13 | AL21: 32000 | AM21: =AL21*AK21 -> 416000
A22: H7 | B22: 16 | C22: TORRE | D22: VALENZUELA | E22: LIDO | F22: 9771848 | K22: 1 | L22: 1 | M22: 1 | N22: 1 | O22: 1 | P22: 1 | Q22: 1 | R22: 1 | S22: 1 | T22: 1 | U22: 1 | V22: 1 | W22: 1 | AK22: =SUM(G22:AJ22) -> 13 | AL22: 32000 | AM22: =AL22*AK22 -> 416000
A23: H7 | B23: 18 | C23: CABRERA | D23: ALARCON | E23: ULICES | F23: 48343664 | K23: 1 | L23: 1 | M23: 1 | N23: 1 | O23: 1 | P23: 1 | Q23: 1 | R23: 1 | S23: 1 | T23: 1 | U23: 1 | V23: 1 | W23: 1 | AK23: =SUM(G23:AJ23) -> 13 | AL23: 32000 | AM23: =AL23*AK23 -> 416000
A24: H7 | B24: 18 | C24: GARCIA | D24: SAAVEDRA | E24: AMERICO | F24: 45198592 | K24: 1 | L24: 1 | M24: 1 | N24: 1 | O24: 1 | P24: 1 | Q24: 1 | R24: 1 | S24: 1 | T24: 1 | U24: 1 | V24: 1 | W24: 1 | AK24: =SUM(G24:AJ24) -> 13 | AL24: 32000 | AM24: =AL24*AK24 -> 416000
A25: H7 | B25: 18 | C25: UQUICHE | D25: FLORES | E25: LUIS | F25: 10523472 | K25: 1 | L25: 1 | M25: 1 | N25: 1 | O25: 1 | P25: 1 | Q25: 1 | R25: 1 | S25: 1 | T25: 1 | U25: 1 | V25: 1 | W25: 1 | X25: 1 | AK25: =SUM(G25:AJ25) -> 14 | AL25: 32000 | AM25: =AL25*AK25 -> 448000
A26: H7 | B26: 19 | C26: HUAMACTO | D26: VIVANCO | E26: ALDO | F26: 41104021 | K26: 1 | L26: 1 | M26: 1 | N26: 1 | O26: 1 | P26: 1 | Q26: 1 | R26: 1 | S26: 1 | T26: 1 | U26: 1 | V26: 1 | W26: 1 | AK26: =SUM(G26:AJ26) -> 13 | AL26: 32000 | AM26: =AL26*AK26 -> 416000
A27: H7 | B27: 19 | C27: PIO | D27: MICHUY | E27: LADISLAO | F27: 336555392 | K27: 1 | L27: 1 | M27: 1 | N27: 1 | O27: 1 | P27: 1 | Q27: 1 | R27: 1 | S27: 1 | T27: 1 | U27: 1 | V27: 1 | W27: 1 | AK27: =SUM(G27:AJ27) -> 13 | AL27: 32000 | AM27: =AL27*AK27 -> 416000
A28: H7 | B28: 20 | C28: CIRIACO | D28: PASCUAL | E28: EDSON | F28: 10756831 | K28: 1 | L28: 1 | M28: 1 | N28: 1 | O28: 1 | P28: 1 | Q28: 1 | R28: 1 | S28: 1 | T28: 1 | U28: 1 | V28: 1 | W28: 1 | AK28: =SUM(G28:AJ28) -> 13 | AL28: 32000 | AM28: =AL28*AK28 -> 416000
A29: H7 | B29: 20 | C29: GONZALES | D29: PALOMINO | E29: LUIS | F29: 44495014 | K29: 1 | L29: 1 | M29: 1 | N29: 1 | O29: 1 | P29: 1 | Q29: 1 | R29: 1 | S29: 1 | T29: 1 | U29: 1 | V29: 1 | W29: 1 | AK29: =SUM(G29:AJ29) -> 13 | AL29: 32000 | AM29: =AL29*AK29 -> 416000
A30: H7 | B30: 21 | C30: MAURICIO | D30: VELASQUEZ | E30: HELBER | F30: 3684789 | K30: 1 | L30: 1 | M30: 1 | N30: 1 | O30: 1 | P30: 1 | Q30: 1 | R30: 1 | S30: 1 | T30: 1 | U30: 1 | V30: 1 | W30: 1 | AK30: =SUM(G30:AJ30) -> 13 | AL30: 32000 | AM30: =AL30*AK30 -> 416000
A31: H7 | B31: 21 | C31: TUESTA | D31: DANTAS | E31: RAUL | F31: 10280884 | K31: 1 | L31: 1 | M31: 1 | N31: 1 | O31: 1 | P31: 1 | Q31: 1 | R31: 1 | S31: 1 | T31: 1 | U31: 1 | V31: 1 | W31: 1 | AK31: =SUM(G31:AJ31) -> 13 | AL31: 32000 | AM31: =AL31*AK31 -> 416000
A32: H7 | B32: 24 | C32: BEJAR | D32: QUISPE | E32: CARLOS | F32: 43811755 | K32: 1 | L32: 1 | M32: 1 | N32: 1 | O32: 1 | P32: 1 | Q32: 1 | R32: 1 | S32: 1 | T32: 1 | U32: 1 | V32: 1 | W32: 1 | X32: 1 | AK32: =SUM(G32:AJ32) -> 14 | AL32: 32000 | AM32: =AL32*AK32 -> 448000
A33: H7 | B33: 24 | C33: OTERO | D33: ELLEN | E33: EVER | F33: 41340550 | K33: 1 | L33: 1 | M33: 1 | N33: 1 | O33: 1 | P33: 1 | Q33: 1 | R33: 1 | S33: 1 | T33: 1 | U33: 1 | V33: 1 | W33: 1 | X33: 1 | AK33: =SUM(G33:AJ33) -> 14 | AL33: 32000 | AM33: =AL33*AK33 -> 448000
A34: H7 | B34: 25 | C34: MONTALVO | D34: JIMENEZ | E34: ERICK | F34: 42606296 | K34: 1 | L34: 1 | M34: 1 | N34: 1 | O34: 1 | P34: 1 | Q34: 1 | R34: 1 | S34: 1 | T34: 1 | U34: 1 | V34: 1 | W34: 1 | X34: 1 | AK34: =SUM(G34:AJ34) -> 14 | AL34: 32000 | AM34: =AL34*AK34 -> 448000
A35: H7 | B35: 25 | C35: PANDURO | D35: DIAZ | E35: BILLY | F35: 48311078 | K35: 1 | L35: 1 | M35: 1 | N35: 1 | O35: 1 | P35: 1 | Q35: 1 | R35: 1 | S35: 1 | T35: 1 | U35: 1 | V35: 1 | W35: 1 | X35: 1 | AK35: =SUM(G35:AJ35) -> 14 | AL35: 32000 | AM35: =AL35*AK35 -> 448000
A36: H7 | B36: 26 | C36: GUTIERREZ | D36: PAYE | E36: ELIAS | F36: 336557895 | K36: 1 | L36: 1 | M36: 1 | N36: 1 | O36: 1 | P36: 1 | Q36: 1 | R36: 1 | S36: 1 | T36: 1 | U36: 1 | V36: 1 | W36: 1 | AK36: =SUM(G36:AJ36) -> 13 | AL36: 32000 | AM36: =AL36*AK36 -> 416000
A37: H7 | B37: 26 | C37: SANCHEZ | D37: HANCCO | E37: WILSON | F37: 444849118 | K37: 1 | L37: 1 | M37: 1 | N37: 1 | O37: 1 | P37: 1 | Q37: 1 | R37: 1 | S37: 1 | T37: 1 | U37: 1 | V37: 1 | W37: 1 | AK37: =SUM(G37:AJ37) -> 13 | AL37: 32000 | AM37: =AL37*AK37 -> 416000
A38: H7 | B38: 27 | C38: MACHICADO | D38: MAMANI | E38: JONY | F38: 336557623 | K38: 1 | L38: 1 | M38: 1 | N38: 1 | O38: 1 | P38: 1 | Q38: 1 | R38: 1 | S38: 1 | T38: 1 | U38: 1 | V38: 1 | W38: 1 | AK38: =SUM(G38:AJ38) -> 13 | AL38: 32000 | AM38: =AL38*AK38 -> 416000
A39: H7 | B39: 27 | C39: CCACCALA | D39: YOMPOSI | E39: JESUS | F39: 444849967 | K39: 1 | L39: 1 | M39: 1 | N39: 1 | O39: 1 | P39: 1 | Q39: 1 | R39: 1 | S39: 1 | T39: 1 | U39: 1 | V39: 1 | W39: 1 | AK39: =SUM(G39:AJ39) -> 13 | AL39: 32000 | AM39: =AL39*AK39 -> 416000
A40: H7 | B40: 28 | C40: BALDEON | D40: PEÑA | E40: CLEMENTE | F40: 43530762 | K40: 1 | L40: 1 | M40: 1 | N40: 1 | O40: 1 | P40: 1 | Q40: 1 | R40: 1 | S40: 1 | T40: 1 | U40: 1 | V40: 1 | W40: 1 | X40: 1 | AK40: =SUM(G40:AJ40) -> 14 | AL40: 32000 | AM40: =AL40*AK40 -> 448000
A41: H7 | B41: 28 | C41: CAYLLAHUA | D41: ANGELINO | E41: HUGO | F41: 15427557 | K41: 1 | L41: 1 | M41: 1 | N41: 1 | O41: 1 | P41: 1 | Q41: 1 | R41: 1 | S41: 1 | T41: 1 | U41: 1 | V41: 1 | W41: 1 | X41: 1 | AK41: =SUM(G41:AJ41) -> 14 | AL41: 32000 | AM41: =AL41*AK41 -> 448000
A42: H7 | B42: 28 | C42: HUAMAN | D42: PAUCAR | E42: JUVELIO | F42: 23258255 | K42: 1 | L42: 1 | M42: 1 | N42: 1 | O42: 1 | P42: 1 | Q42: 1 | R42: 1 | S42: 1 | T42: 1 | U42: 1 | V42: 1 | W42: 1 | X42: 1 | AK42: =SUM(G42:AJ42) -> 14 | AL42: 32000 | AM42: =AL42*AK42 -> 448000
A43: H7 | B43: 29 | C43: DIAZ | D43: CALLE | E43: ODAR | F43: 44790108 | K43: 1 | L43: 1 | M43: 1 | N43: 1 | O43: 1 | P43: 1 | Q43: 1 | R43: 1 | S43: 1 | T43: 1 | U43: 1 | V43: 1 | W43: 1 | X43: 1 | AK43: =SUM(G43:AJ43) -> 14 | AL43: 32000 | AM43: =AL43*AK43 -> 448000
A44: H7 | B44: 29 | C44: VILLAR | D44: FLORES | E44: EDGAR | F44: 9311864 | K44: 1 | L44: 1 | M44: 1 | N44: 1 | O44: 1 | P44: 1 | Q44: 1 | R44: 1 | S44: 1 | T44: 1 | U44: 1 | V44: 1 | W44: 1 | X44: 1 | AK44: =SUM(G44:AJ44) -> 14 | AL44: 32000 | AM44: =AL44*AK44 -> 448000
A45: H7 | B45: 30 | C45: CHURATA | D45: CHUQUIJA | E45: ELISEO | F45: 10646296 | K45: 1 | L45: 1 | M45: 1 | N45: 1 | O45: 1 | P45: 1 | Q45: 1 | R45: 1 | S45: 1 | T45: 1 | U45: 1 | V45: 1 | W45: 1 | X45: 1 | AK45: =SUM(G45:AJ45) -> 14 | AL45: 32000 | AM45: =AL45*AK45 -> 448000
A46: H7 | B46: 30 | C46: MATO | D46: FLORES | E46: ISAAC | F46: 42293469 | K46: 1 | L46: 1 | M46: 1 | N46: 1 | O46: 1 | P46: 1 | Q46: 1 | R46: 1 | S46: 1 | T46: 1 | U46: 1 | V46: 1 | W46: 1 | X46: 1 | AK46: =SUM(G46:AJ46) -> 14 | AL46: 32000 | AM46: =AL46*AK46 -> 448000
G48: =SUM(G10:G47) -> 0 | H48: =SUM(H10:H47) -> 0 | I48: =SUM(I10:I47) -> 0 | J48: =SUM(J10:J47) -> 0 | K48: =SUM(K10:K47) -> 37 | L48: =SUM(L10:L47) -> 37 | M48: =SUM(M10:M47) -> 37 | N48: =SUM(N10:N47) -> 37 | ... AK48: =SUM(AK10:AK47) -> 498
...

Sheet ACONCAGUA
A6: CORRELATIVO N°3 | G6: 45809 | H6: 45810 | I6: 45811 | J6: 45812 | K6: 45813 | L6: 45814 | M6: 45815 | N6: 45816 | O6: 45817 | P6: 45818 | Q6: 45819 | R6: 45820 | S6: 45821 | T6: 45822 | U6: 45823 | V6: 45824 | W6: 45825 | X6: 45826 | Y6: 45827 | Z6: 45828 | AA6: 45829 | AB6: 45830 | AC6: 45831 | AD6: 45832 | AE6: 45833 | AF6: 45834 | AG6: 45835 | AH6: 45836 | AI6: 45837 | AJ6: 45838 | AK6: 01 AL 30 DE JUNIO
B9: HAB | C9: APELLIDO PATERNO | D9: APELLIDO MATERNO | E9: NOMBRE | F9: RUT | AK9: D. OCUP | AL9: V. OCUP | AM9: T. OCUP.
A10: AC | B10: 205 | C10: DÍAZ | E10: VALENTINA | F10: 17764546-K | G10: 1 | H10: 1 | I10: 1 | AK10: =SUM(G10:AJ10) -> 3 | AL10: 33000 | AM10: =AL10*AK10 -> 99000
A11: AC | B11: 205 | C11: CARRASCO | E11: CINTHIA | F11: 19278451-3 | G11: 1 | H11: 1 | I11: 1 | AK11: =SUM(G11:AJ11) -> 3 | AL11: 33000 | AM11: =AL11*AK11 -> 99000
A12: AC | B12: 302 | C12: OLIVARES | E12: GONZALO | F12: 18843149-6 | G12: 1 | H12: 1 | I12: 1 | AK12: =SUM(G12:AJ12) -> 3 | AL12: 33000 | AM12: =AL12*AK12 -> 99000
A13: AC | B13: 302 | C13: SEPULVEDA | E13: FERNANDO | F13: 17319810-8 | G13: 1 | H13: 1 | I13: 1 | AK13: =SUM(G13:AJ13) -> 3 | AL13: 33000 | AM13: =AL13*AK13 -> 99000
A14: AC | B14: 404 | C14: BRUNA | E14: EDUARDO | F14: 16325978-8 | G14: 1 | H14: 1 | I14: 1 | AK14: =SUM(G14:AJ14) -> 3 | AL14: 33000 | AM14: =AL14*AK14 -> 99000
A15: AC | B15: 404 | C15: QUEVEDO | E15: CRISTÓBAL | F15: 19359014-4 | G15: 1 | H15: 1 | I15: 1 | AK15: =SUM(G15:AJ15) -> 3 | AL15: 33000 | AM15: =AL15*AK15 -> 99000
A16: AC | B16: 604 | C16: GALAZ | D16: GONZALEZ | E16: ALEJANDRO | F16: 19527019-8 | G16: 1 | H16: 1 | I16: 1 | AK16: =SUM(G16:AJ16) -> 3 | AL16: 33000 | AM16: =AL16*AK16 -> 99000
A17: AC | B17: 604 | C17: PINTO | E17: CLAUDIO | F17: 13726534-6 | G17: 1 | H17: 1 | I17: 1 | AK17: =SUM(G17:AJ17) -> 3 | AL17: 33000 | AM17: =AL17*AK17 -> 99000
A18: AC | B18: 903 | C18: CUETO | E18: SUSANA | F18: 13225829-5 | G18: 1 | H18: 1 | I18: 1 | AK18: =SUM(G18:AJ18) -> 3 | AL18: 33000 | AM18: =AL18*AK18 -> 99000
A19: AC | B19: 903 | C19: TOLOZA | E19: KATHERINE | F19: 15188041-k | G19: 1 | H19: 1 | I19: 1 | AK19: =SUM(G19:AJ19) -> 3 | AL19: 33000 | AM19: =AL19*AK19 -> 99000
A20: AC | B20: 1101 | C20: PINOCHET | E20: CONSUELO | F20: 17904147-2 | G20: 1 | H20: 1 | I20: 1 | AK20: =SUM(G20:AJ20) -> 3 | AL20: 33000 | AM20: =AL20*AK20 -> 99000
A21: AC | B21: 1101 | C21: SANDOVAL | E21: GISELA | F21: 19120950-8 | G21: 1 | H21: 1 | I21: 1 | AK21: =SUM(G21:AJ21) -> 3 | AL21: 33000 | AM21: =AL21*AK21 -> 99000
A22: AC | B22: 1402 | C22: VILLARREAL | E22: EDWAR | G22: 1 | H22: 1 | I22: 1 | AK22: =SUM(G22:AJ22) -> 3 | AL22: 33000 | AM22: =AL22*AK22 -> 99000
A23: AC | B23: 1402 | C23: HERMOSILLA | E23: HÉCTOR | F23: 19297281-7 | G23: 1 | H23: 1 | I23: 1 | AK23: =SUM(G23:AJ23) -> 3 | AL23: 33000 | AM23: =AL23*AK23 -> 99000
A24: AC | B24: 401 | C24: SOTO | D24: HERRERA | E24: MARIA | F24: 19797369-2 | H24: 1 | I24: 1 | AK24: =SUM(G24:AJ24) -> 2 | AL24: 60000 | AM24: =AL24*AK24 -> 120000
A25: AC | B25: 205 | C25: ZARATE | E25: FABIAN | F25: 18150201-0 | J25: 1 | K25: 1 | L25: 1 | M25: 1 | N25: 1 | O25: 1 | AK25: =SUM(G25:AJ25) -> 6 | AL25: 33000 | AM25: =AL25*AK25 -> 198000
A26: AC | B26: 205 | C26: SEPULVEDA | E26: GONZALO | F26: 18408247-0 | J26: 1 | K26: 1 | L26: 1 | M26: 1 | N26: 1 | O26: 1 | AK26: =SUM(G26:AJ26) -> 6 | AL26: 33000 | AM26: =AL26*AK26 -> 198000
A27: AC | B27: 302 | C27: BERNARD | E27: FERNANDO | F27: 17137085-K | J27: 1 | K27: 1 | L27: 1 | M27: 1 | N27: 1 | O27: 1 | AK27: =SUM(G27:AJ27) -> 6 | AL27: 33000 | AM27: =AL27*AK27 -> 198000
A28: AC | B28: 302 | C28: ARCHILES | E28: FELIX | F28: 17137111-2 | J28: 1 | K28: 1 | L28: 1 | M28: 1 | N28: 1 | O28: 1 | AK28: =SUM(G28:AJ28) -> 6 | AL28: 33000 | AM28: =AL28*AK28 -> 198000
A29: AC | B29: 401 | C29: SOTO | D29: HERRERA | E29: MARIA | F29: 19797369-2 | J29: 1 | K29: 1 | L29: 1 | M29: 1 | N29: 1 | O29: 1 | AK29: =SUM(G29:AJ29) -> 6 | AL29: 60000 | AM29: =AL29*AK29 -> 360000
A30: AC | B30: 404 | C30: TENORIO | E30: JOSE | F30: 19365127-5 | J30: 1 | K30: 1 | L30: 1 | M30: 1 | N30: 1 | O30: 1 | AK30: =SUM(G30:AJ30) -> 6 | AL30: 33000 | AM30: =AL30*AK30 -> 198000
A31: AC | B31: 404 | C31: CARRASCO | E31: FELIPE | F31: 16690731-4 | J31: 1 | K31: 1 | L31: 1 | M31: 1 | N31: 1 | O31: 1 | AK31: =SUM(G31:AJ31) -> 6 | AL31: 33000 | AM31: =AL31*AK31 -> 198000
A32: AC | B32: 604 | C32: AGUILERA | E32: JORGE | F32: 19797369-2 | J32: 1 | K32: 1 | L32: 1 | M32: 1 | N32: 1 | O32: 1 | AK32: =SUM(G32:AJ32) -> 6 | AL32: 33000 | AM32: =AL32*AK32 -> 198000
A33: AC | B33: 604 | C33: AZOCAR | D33: CORNEJO | E33: NICOLAS | F33: 19114498-8 | J33: 1 | K33: 1 | L33: 1 | M33: 1 | N33: 1 | O33: 1 | AK33: =SUM(G33:AJ33) -> 6 | AL33: 33000 | AM33: =AL33*AK33 -> 198000
A34: AC | B34: 903 | C34: CERECEDA | E34: SOLANGE | F34: 17172403-1 | J34: 1 | K34: 1 | L34: 1 | M34: 1 | N34: 1 | O34: 1 | AK34: =SUM(G34:AJ34) -> 6 | AL34: 33000 | AM34: =AL34*AK34 -> 198000
A35: AC | B35: 903 | C35: PEREZ | E35: MARIA F | F35: 18785701-5 | J35: 1 | K35: 1 | L35: 1 | M35: 1 | N35: 1 | O35: 1 | AK35: =SUM(G35:AJ35) -> 6 | AL35: 33000 | AM35: =AL35*AK35 -> 198000
A36: AC | B36: 1101 | C36: BARRIENTOS | D36: URQUIZA | E36: ROCIO | F36: 19907354-0 | J36: 1 | K36: 1 | L36: 1 | M36: 1 | N36: 1 | O36: 1 | AK36: =SUM(G36:AJ36) -> 6 | AL36: 33000 | AM36: =AL36*AK36 -> 198000
A37: AC | B37: 1101 | C37: VALENZUELA | D37: BUSTOS | E37: VICTORIA | F37: 19120001-2 | J37: 1 | K37: 1 | L37: 1 | M37: 1 | N37: 1 | O37: 1 | AK37: =SUM(G37:AJ37) -> 6 | AL37: 33000 | AM37: =AL37*AK37 -> 198000
A38: AC | B38: 1402 | C38: CORNEJO | D38: OCHOA | E38: RONALD | F38: 13507456-K | J38: 1 | K38: 1 | L38: 1 | M38: 1 | N38: 1 | O38: 1 | AK38: =SUM(G38:AJ38) -> 6 | AL38: 33000 | AM38: =AL38*AK38 -> 198000
A39: AC | B39: 1402 | C39: DUARTE | D39: GOMEZ | E39: JORGE | F39: 9635487-8 | J39: 1 | K39: 1 | L39: 1 | M39: 1 | N39: 1 | O39: 1 | AK39: =SUM(G39:AJ39) -> 6 | AL39: 33000 | AM39: =AL39*AK39 -> 198000
A40: AC | B40: 205 | C40: ZARATE | E40: FABIAN | F40: 18150201-0 | P40: 1 | AK40: =SUM(G40:AJ40) -> 1 | AL40: 33000 | AM40: =AL40*AK40 -> 33000
A41: AC | B41: 205 | C41: SEPULVEDA | E41: GONZALO | F41: 18408247-0 | P41: 1 | AK41: =SUM(G41:AJ41) -> 1 | AL41: 33000 | AM41: =AL41*AK41 -> 33000
A42: AC | B42: 302 | C42: BERNARD | E42: FERNANDO | F42: 17137085-K | P42: 1 | AK42: =SUM(G42:AJ42) -> 1 | AL42: 33000 | AM42: =AL42*AK42 -> 33000
A43: AC | B43: 302 | C43: AGUILERA | E43: JORGE | F43: 19122318-7 | P43: 1 | AK43: =SUM(G43:AJ43) -> 1 | AL43: 33000 | AM43: =AL43*AK43 -> 33000
A44: AC | B44: 401 | C44: ARROYO | D44: CAMPOS | E44: PATRICIO | F44: 14472229-9 | P44: 1 | AK44: =SUM(G44:AJ44) -> 1 | AL44: 60000 | AM44: =AL44*AK44 -> 60000
A45: AC | B45: 404 | C45: TENORIO | E45: JOSE | F45: 19365127-5 | P45: 1 | AK45: =SUM(G45:AJ45) -> 1 | AL45: 33000 | AM45: =AL45*AK45 -> 33000
A46: AC | B46: 404 | C46: CARRASCO | E46: FELIPE | F46: 16690731-4 | P46: 1 | AK46: =SUM(G46:AJ46) -> 1 | AL46: 33000 | AM46: =AL46*AK46 -> 33000
A47: AC | B47: 604 | C47: ARCHILES | E47: FELIX | F47: 17137111-2 | P47: 1 | AK47: =SUM(G47:AJ47) -> 1 | AL47: 33000 | AM47: =AL47*AK47 -> 33000
...
